Workbook
Name Slicer_Diabetes_Status: #N/A
Name Slicer_Weight_Status: #N/A

Sheet Customer Names
A1: Customer ID | B1: Title | C1: First name | D1: Last Name
A2: Id1 | B2: Ms | C2: Kelly | D2: Hawks
A3: Id2 | B3: Mr | C3: Matthew D | D3: Lehner
A4: Id3 | B4: Mr | C4: Phil | D4: Lu
A5: Id4 | B5: Ms | C5: Kelsey | D5: Osborne
A6: Id5 | B6: Ms | C6: Kristyn | D6: Kadala
A7: Id6 | B7: Mr | C7: Russell B | D7: Baker
A8: Id7 | B8: Mr | C8: Scott | D8: Macpherson
A9: Id8 | B9: Mr | C9: Stephen | D9: Hallman
A10: Id9 | B10: Mr | C10: Patrick R | D10: Moran
A11: Id10 | B11: Ms | C11: Brooke N | D11: Benner
A12: Id11 | B12: Ms | C12: Paola Andrea | D12: Fierro Vargas
... A72: Id71 | B72: Mr | C72: Jeff | D72: Turner
A73: Id72 | B73: Mr | C73: Elenilton V | D73: Rangel | E73: Sr
A74: Id73 | B74: Ms | C74: Maurya | D74: Lacey
A75: Id74 | B75: Ms | C75: Samantha C | D75: Stiger
A76: Id75 | B76: Ms | C76: Bethany A | D76: Caldwell
A77: Id76 | B77: Mr | C77: Yves | D77: Marmillod
A78: Id77 | B78: Ms | C78: Danielle | D78: Cloutier-Simons
A79: Id78 | B79: Ms | C79: Julia | D79: Vegas
A80: Id79 | B80: Mr | C80: Joshua | D80: Cochran
A81: Id80 | B81: Ms | C81: Jennifer | D81: Holtzapple
A82: Id81 | B82: Ms | C82: Gwen M | D82: Meyer
A83: Id82 | B83: Mr | C83: Patrick | D83: Brickley
A84: Id83 | B84: Ms | C84: Kate | D84: Magee
A85: Id84 | B85: Mr | C85: Kevin | D85: Thoma
... A188: Id187 | B188: Mr | C188: Andrew P | D188: Dublin
A189: Id188 | B189: Mr | C189: George M | D189: Cleland | E189: V
A190: Id189 | B190: Ms | C190: Sarah | D190: Evans
A191: Id190 | B191: Ms | C191: Lara | D191: Boyd
A192: Id191 | B192: Mr | C192: Sebastien | D192: Roulier
A193: Id192 | B193: Mr | C193: Padraig | D193: Mullins
A194: Id193 | B194: Ms | C194: Heather | D194: Hofmann
A195: Id194 | B195: Mr | C195: Jorge | D195: Garcia Garcia
A196: Id195 | B196: Mr | C196: Jack R | D196: Klecker
A197: Id196 | B197: Mr | C197: Felix | D197: Cancre
A198: Id197 | B198: Mr | C198: Christopher C | D198: Denucci
A199: Id198 | B199: Mr | C199: Jesse | D199: Saldana
A200: Id199 | B200: Ms | C200: Jill | D200: Weinberg
A201: Id200 | B201: Mr | C201: William | D201: Walsh
...

Sheet Medical Examinations
A1: Customer ID | B1: BMI | C1: HBA1C | D1: Heart Issues | E1: Any Transplants | F1: Cancer history | G1: NumberOfMajorSurgeries | H1: smoker | I1: Weight Status | J1: Diabetes Status
A2: Id1 | B2: 47.41 | C2: 7.47 | D2: No | E2: No | F2: No | G2: 0 | H2: yes | I2: {=_xlfn.IFS(B248<18.5,"Underweight",B248<25,"Normal Weight",B248<30,"Overweight",B248>=30,"Obesity")} -> Overweight | J2: {=_xlfn.IFS(C2<5.7,"Normal",C2<6.5,"Pre-Diabetes",C2>=6.5,"Diabetes")} -> Diabetes
A3: Id2 | B3: 30.36 | C3: 5.77 | D3: No | E3: No | F3: No | G3: 0 | H3: yes | I3: {=_xlfn.IFS(B249<18.5,"Underweight",B249<25,"Normal Weight",B249<30,"Overweight",B249>=30,"Obesity")} -> Obesity | J3: {=_xlfn.IFS(C3<5.7,"Normal",C3<6.5,"Pre-Diabetes",C3>=6.5,"Diabetes")} -> Pre-Diabetes
A4: Id3 | B4: 34.485 | C4: 11.87 | D4: yes | E4: No | F4: No | G4: 2 | H4: yes | I4: {=_xlfn.IFS(B250<18.5,"Underweight",B250<25,"Normal Weight",B250<30,"Overweight",B250>=30,"Obesity")} -> Obesity | J4: {=_xlfn.IFS(C4<5.7,"Normal",C4<6.5,"Pre-Diabetes",C4>=6.5,"Diabetes")} -> Diabetes
A5: Id4 | B5: 38.095 | C5: 6.05 | D5: No | E5: No | F5: No | G5: 0 | H5: yes | I5: {=_xlfn.IFS(B251<18.5,"Underweight",B251<25,"Normal Weight",B251<30,"Overweight",B251>=30,"Obesity")} -> Obesity | J5: {=_xlfn.IFS(C5<5.7,"Normal",C5<6.5,"Pre-Diabetes",C5>=6.5,"Diabetes")} -> Pre-Diabetes
A6: Id5 | B6: 35.53 | C6: 5.45 | D6: No | E6: No | F6: No | G6: 0 | H6: yes | I6: {=_xlfn.IFS(B252<18.5,"Underweight",B252<25,"Normal Weight",B252<30,"Overweight",B252>=30,"Obesity")} -> Obesity | J6: {=_xlfn.IFS(C6<5.7,"Normal",C6<6.5,"Pre-Diabetes",C6>=6.5,"Diabetes")} -> Normal
A7: Id6 | B7: 32.8 | C7: 6.59 | D7: No | E7: No | F7: No | G7: 0 | H7: yes | I7: {=_xlfn.IFS(B253<18.5,"Underweight",B253<25,"Normal Weight",B253<30,"Overweight",B253>=30,"Obesity")} -> Obesity | J7: {=_xlfn.IFS(C7<5.7,"Normal",C7<6.5,"Pre-Diabetes",C7>=6.5,"Diabetes")} -> Diabetes
A8: Id7 | B8: 36.4 | C8: 6.07 | D8: No | E8: No | F8: No | G8: 0 | H8: yes | I8: {=_xlfn.IFS(B254<18.5,"Underweight",B254<25,"Normal Weight",B254<30,"Overweight",B254>=30,"Obesity")} -> Obesity | J8: {=_xlfn.IFS(C8<5.7,"Normal",C8<6.5,"Pre-Diabetes",C8>=6.5,"Diabetes")} -> Pre-Diabetes
A9: Id8 | B9: 36.96 | C9: 7.93 | D9: No | E9: No | F9: No | G9: 3 | H9: yes | I9: {=_xlfn.IFS(B255<18.5,"Underweight",B255<25,"Normal Weight",B255<30,"Overweight",B255>=30,"Obesity")} -> Obesity | J9: {=_xlfn.IFS(C9<5.7,"Normal",C9<6.5,"Pre-Diabetes",C9>=6.5,"Diabetes")} -> Diabetes
A10: Id9 | B10: 41.14 | C10: 9.58 | D10: yes | E10: No | F10: Yes | G10: 1 | H10: yes | I10: {=_xlfn.IFS(B256<18.5,"Underweight",B256<25,"Normal Weight",B256<30,"Overweight",B256>=30,"Obesity")} -> Normal Weight | J10: {=_xlfn.IFS(C10<5.7,"Normal",C10<6.5,"Pre-Diabetes",C10>=6.5,"Diabetes")} -> Diabetes
A11: Id10 | B11: 38.06 | C11: 10.79 | D11: No | E11: No | F11: No | G11: 0 | H11: yes | I11: {=_xlfn.IFS(B257<18.5,"Underweight",B257<25,"Normal Weight",B257<30,"Overweight",B257>=30,"Obesity")} -> Obesity | J11: {=_xlfn.IFS(C11<5.7,"Normal",C11<6.5,"Pre-Diabetes",C11>=6.5,"Diabetes")} -> Diabetes
A12: Id11 | B12: 37.7 | C12: 5.96 | D12: yes | E12: No | F12: No | G12: 2 | H12: yes | I12: {=_xlfn.IFS(B258<18.5,"Underweight",B258<25,"Normal Weight",B258<30,"Overweight",B258>=30,"Obesity")} -> Obesity | J12: {=_xlfn.IFS(C12<5.7,"Normal",C12<6.5,"Pre-Diabetes",C12>=6.5,"Diabetes")} -> Pre-Diabetes
A13: Id12 | B13: 42.13 | C13: 11.9 | D13: No | E13: No | F13: No | G13: 0 | H13: yes | I13: {=_xlfn.IFS(B259<18.5,"Underweight",B259<25,"Normal Weight",B259<30,"Overweight",B259>=30,"Obesity")} -> Obesity | J13: {=_xlfn.IFS(C13<5.7,"Normal",C13<6.5,"Pre-Diabetes",C13>=6.5,"Diabetes")} -> Diabetes
... A2336: Id2335 | B2336: 17.58 | C2336: 4.51 | D2336: No | E2336: No | F2336: No | G2336: 1 | H2336: No | I2336: {=_xlfn.IFS(B2582<18.5,"Underweight",B2582<25,"Normal Weight",B2582<30,"Overweight",B2582>=30,"Obesity")} -> Underweight | J2336: {=_xlfn.IFS(C2336<5.7,"Normal",C2336<6.5,"Pre-Diabetes",C2336>=6.5,"Diabetes")} -> Normal

Sheet Hospitalisation Details
A1: Customer ID | B1: year | C1: month | D1: date | E1: Date Of Birth | F1: charges | G1: Hospital tier | H1: City tier | I1: State ID | J1: Age | K1: children
A2: Id1793 | B2: 1995 | C2: Dec | D2: 1 | E2: =CONCATENATE(D2,"-",C2,"-",B2) -> 1-Dec-1995 | F2: 4827.9 | G2: tier - 1 | H2: tier - 2 | I2: Unknown | J2: =DATEDIF(E2,"08-6-2023","y") -> 27 | K2: 3
A3: Id170 | B3: 2000 | C3: Sep | D3: 5 | E3: =CONCATENATE(D3,"-",C3,"-",B3) -> 5-Sep-2000 | F3: 37165.16 | G3: tier - 1 | H3: tier - 3 | I3: Unknown | J3: =DATEDIF(E3,"08-6-2023","y") -> 22 | K3: 1
A4: Id2335 | B4: 1992 | C4: Jul | D4: 9 | E4: =CONCATENATE(D4,"-",C4,"-",B4) -> 9-Jul-1992 | F4: 563.84 | G4: tier - 2 | H4: tier - 3 | I4: R1013 | J4: =DATEDIF(E4,"08-6-2023","y") -> 30 | K4: 0
A5: Id2334 | B5: 1992 | C5: Nov | D5: 30 | E5: =CONCATENATE(D5,"-",C5,"-",B5) -> 30-Nov-1992 | F5: 570.62 | G5: tier - 2 | H5: tier - 1 | I5: R1013 | J5: =DATEDIF(E5,"08-6-2023","y") -> 30 | K5: 0
A6: Id2333 | B6: 1993 | C6: Jun | D6: 30 | E6: =CONCATENATE(D6,"-",C6,"-",B6) -> 30-Jun-1993 | F6: 600 | G6: tier - 2 | H6: tier - 1 | I6: R1013 | J6: =DATEDIF(E6,"08-6-2023","y") -> 29 | K6: 0
A7: Id2332 | B7: 1992 | C7: Sep | D7: 13 | E7: =CONCATENATE(D7,"-",C7,"-",B7) -> 13-Sep-1992 | F7: 604.54 | G7: tier - 3 | H7: tier - 3 | I7: R1013 | J7: =DATEDIF(E7,"08-6-2023","y") -> 30 | K7: 0
A8: Id2331 | B8: 1998 | C8: Jul | D8: 27 | E8: =CONCATENATE(D8,"-",C8,"-",B8) -> 27-Jul-1998 | F8: 637.26 | G8: tier - 3 | H8: tier - 3 | I8: R1013 | J8: =DATEDIF(E8,"08-6-2023","y") -> 24 | K8: 0
A9: Id2330 | B9: 2001 | C9: Nov | D9: 20 | E9: =CONCATENATE(D9,"-",C9,"-",B9) -> 20-Nov-2001 | F9: 646.14 | G9: tier - 3 | H9: tier - 3 | I9: R1012 | J9: =DATEDIF(E9,"08-6-2023","y") -> 21 | K9: 0
A10: Id2329 | B10: 1993 | C10: Jun | D10: 1 | E10: =CONCATENATE(D10,"-",C10,"-",B10) -> 1-Jun-1993 | F10: 650 | G10: tier - 3 | H10: tier - 3 | I10: R1013 | J10: =DATEDIF(E10,"08-6-2023","y") -> 30 | K10: 0
A11: Id2328 | B11: 1995 | C11: Jul | D11: 4 | E11: =CONCATENATE(D11,"-",C11,"-",B11) -> 4-Jul-1995 | F11: 650 | G11: tier - 3 | H11: tier - 3 | I11: R1013 | J11: =DATEDIF(E11,"08-6-2023","y") -> 27 | K11: 0
A12: Id2327 | B12: 2002 | C12: Nov | D12: 29 | E12: =CONCATENATE(D12,"-",C12,"-",B12) -> 29-Nov-2002 | F12: 668 | G12: tier - 3 | H12: tier - 2 | I12: R1012 | J12: =DATEDIF(E12,"08-6-2023","y") -> 20 | K12: 0
A13: Id2326 | B13: 1997 | C13: Nov | D13: 9 | E13: =CONCATENATE(D13,"-",C13,"-",B13) -> 9-Nov-1997 | F13: 670 | G13: tier - 3 | H13: tier - 3 | I13: R1013 | J13: =DATEDIF(E13,"08-6-2023","y") -> 25 | K13: 0
... A2344: Id1 | B2344: 1968 | C2344: Oct | D2344: 12 | E2344: =CONCATENATE(D2344,"-",C2344,"-",B2344) -> 12-Oct-1968 | F2344: 63770.43 | G2344: tier - 1 | H2344: tier - 3 | I2344: R1013 | J2344: =DATEDIF(E2344,"08-6-2023","y") -> 54 | K2344: 0

Sheet Healthcare
B2: Customer ID | C2: Full Name | D2: BMI | E2: HBA1C | F2: Heart Issues | G2: Any Transplant | H2: Cancer History | I2: NumberOfMajorSurgeries | J2: Smoker | K2: Weight Status | L2: Diabetes Status | M2: DOB | N2: Charges | O2: Hospital Tier | P2: City Tier | Q2: State ID | R2: Age | S2: Age Group
B3: Id1 | C3: =VLOOKUP(B3,'Customer Names'!A$2:D$2336,3,0) -> Kelly | D3: {=_xlfn.XLOOKUP(B3,'Medical Examinations'!A$2:A$2336,'Medical Examinations'!B$2:J$2336)} -> 47.41 | E3: 7.47 | F3: No | G3: No | H3: No | I3: 0 | J3: yes | K3: Overweight | L3: Diabetes | M3: {=_xlfn.XLOOKUP(B3,'Hospitalisation Details'!A$2:A$2344,'Hospitalisation Details'!E$2:J$2344)} -> 12-Oct-1968 | N3: 63770.43 | O3: tier - 1 | P3: tier - 3 | Q3: R1013 | R3: 54 | S3: {=_xlfn.IFS(R3<18,"Below 18",R3<=29,"Young Adults",R3<=44,"Adults",R3<=59,"Middle-Aged Adults",R3<=65,"Older Adults",R3>65,"Above 65")} -> Middle-Aged Adults
B4: Id2 | C4: =VLOOKUP(B4,'Customer Names'!A$2:D$2336,3,0) -> Matthew D | D4: {=_xlfn.XLOOKUP(B4,'Medical Examinations'!A$2:A$2336,'Medical Examinations'!B$2:J$2336)} -> 30.36 | E4: 5.77 | F4: No | G4: No | H4: No | I4: 0 | J4: yes | K4: Obesity | L4: Pre-Diabetes | M4: {=_xlfn.XLOOKUP(B4,'Hospitalisation Details'!A$2:A$2344,'Hospitalisation Details'!E$2:J$2344)} -> 8-Jun-1977 | N4: 62592.87 | O4: tier - 2 | P4: tier - 3 | Q4: R1013 | R4: 46 | S4: {=_xlfn.IFS(R4<18,"Below 18",R4<=29,"Young Adults",R4<=44,"Adults",R4<=59,"Middle-Aged Adults",R4<=65,"Older Adults",R4>65,"Above 65")} -> Middle-Aged Adults
B5: Id3 | C5: =VLOOKUP(B5,'Customer Names'!A$2:D$2336,3,0) -> Phil | D5: {=_xlfn.XLOOKUP(B5,'Medical Examinations'!A$2:A$2336,'Medical Examinations'!B$2:J$2336)} -> 34.485 | E5: 11.87 | F5: yes | G5: No | H5: No | I5: 2 | J5: yes | K5: Obesity | L5: Diabetes | M5: {=_xlfn.XLOOKUP(B5,'Hospitalisation Details'!A$2:A$2344,'Hospitalisation Details'!E$2:J$2344)} -> 11-Sep-1970 | N5: 60021.4 | O5: tier - 1 | P5: tier - 1 | Q5: R1012 | R5: 52 | S5: {=_xlfn.IFS(R5<18,"Below 18",R5<=29,"Young Adults",R5<=44,"Adults",R5<=59,"Middle-Aged Adults",R5<=65,"Older Adults",R5>65,"Above 65")} -> Middle-Aged Adults
B6: Id4 | C6: =VLOOKUP(B6,'Customer Names'!A$2:D$2336,3,0) -> Kelsey | D6: {=_xlfn.XLOOKUP(B6,'Medical Examinations'!A$2:A$2336,'Medical Examinations'!B$2:J$2336)} -> 38.095 | E6: 6.05 | F6: No | G6: No | H6: No | I6: 0 | J6: yes | K6: Obesity | L6: Pre-Diabetes | M6: {=_xlfn.XLOOKUP(B6,'Hospitalisation Details'!A$2:A$2344,'Hospitalisation Details'!E$2:J$2344)} -> 6-Jun-1991 | N6: 58571.07 | O6: tier - 1 | P6: tier - 3 | Q6: R1024 | R6: 32 | S6: {=_xlfn.IFS(R6<18,"Below 18",R6<=29,"Young Adults",R6<=44,"Adults",R6<=59,"Middle-Aged Adults",R6<=65,"Older Adults",R6>65,"Above 65")} -> Adults
B7: Id5 | C7: =VLOOKUP(B7,'Customer Names'!A$2:D$2336,3,0) -> Kristyn | D7: {=_xlfn.XLOOKUP(B7,'Medical Examinations'!A$2:A$2336,'Medical Examinations'!B$2:J$2336)} -> 35.53 | E7: 5.45 | F7: No | G7: No | H7: No | I7: 0 | J7: yes | K7: Obesity | L7: Normal | M7: {=_xlfn.XLOOKUP(B7,'Hospitalisation Details'!A$2:A$2344,'Hospitalisation Details'!E$2:J$2344)} -> 19-Jun-1989 | N7: 55135.4 | O7: tier - 1 | P7: tier - 2 | Q7: R1012 | R7: 33 | S7: {=_xlfn.IFS(R7<18,"Below 18",R7<=29,"Young Adults",R7<=44,"Adults",R7<=59,"Middle-Aged Adults",R7<=65,"Older Adults",R7>65,"Above 65")} -> Adults
B8: Id6 | C8: =VLOOKUP(B8,'Customer Names'!A$2:D$2336,3,0) -> Russell B | D8: {=_xlfn.XLOOKUP(B8,'Medical Examinations'!A$2:A$2336,'Medical Examinations'!B$2:J$2336)} -> 32.8 | E8: 6.59 | F8: No | G8: No | H8: No | I8: 0 | J8: yes | K8: Obesity | L8: Diabetes | M8: {=_xlfn.XLOOKUP(B8,'Hospitalisation Details'!A$2:A$2344,'Hospitalisation Details'!E$2:J$2344)} -> 4-Aug-1962 | N8: 52590.83 | O8: tier - 1 | P8: tier - 3 | Q8: R1011 | R8: 60 | S8: {=_xlfn.IFS(R8<18,"Below 18",R8<=29,"Young Adults",R8<=44,"Adults",R8<=59,"Middle-Aged Adults",R8<=65,"Older Adults",R8>65,"Above 65")} -> Older Adults
B9: Id7 | C9: =VLOOKUP(B9,'Customer Names'!A$2:D$2336,3,0) -> Scott | D9: {=_xlfn.XLOOKUP(B9,'Medical Examinations'!A$2:A$2336,'Medical Examinations'!B$2:J$2336)} -> 36.4 | E9: 6.07 | F9: No | G9: No | H9: No | I9: 0 | J9: yes | K9: Obesity | L9: Pre-Diabetes | M9: {=_xlfn.XLOOKUP(B9,'Hospitalisation Details'!A$2:A$2344,'Hospitalisation Details'!E$2:J$2344)} -> 27-Oct-1994 | N9: 51194.56 | O9: tier - 1 | P9: tier - 3 | Q9: R1011 | R9: 28 | S9: {=_xlfn.IFS(R9<18,"Below 18",R9<=29,"Young Adults",R9<=44,"Adults",R9<=59,"Middle-Aged Adults",R9<=65,"Older Adults",R9>65,"Above 65")} -> Young Adults
B10: Id8 | C10: =VLOOKUP(B10,'Customer Names'!A$2:D$2336,3,0) -> Stephen | D10: {=_xlfn.XLOOKUP(B10,'Medical Examinations'!A$2:A$2336,'Medical Examinations'!B$2:J$2336)} -> 36.96 | E10: 7.93 | F10: No | G10: No | H10: No | I10: 3 | J10: yes | K10: Obesity | L10: Diabetes | M10: {=_xlfn.XLOOKUP(B10,'Hospitalisation Details'!A$2:A$2344,'Hospitalisation Details'!E$2:J$2344)} -> 27-Jun-1958 | N10: 49577.66 | O10: tier - 2 | P10: tier - 2 | Q10: R1013 | R10: 64 | S10: {=_xlfn.IFS(R10<18,"Below 18",R10<=29,"Young Adults",R10<=44,"Adults",R10<=59,"Middle-Aged Adults",R10<=65,"Older Adults",R10>65,"Above 65")} -> Older Adults
B11: Id9 | C11: =VLOOKUP(B11,'Customer Names'!A$2:D$2336,3,0) -> Patrick R | D11: {=_xlfn.XLOOKUP(B11,'Medical Examinations'!A$2:A$2336,'Medical Examinations'!B$2:J$2336)} -> 41.14 | E11: 9.58 | F11: yes | G11: No | H11: Yes | I11: 1 | J11: yes | K11: Normal Weight | L11: Diabetes | M11: {=_xlfn.XLOOKUP(B11,'Hospitalisation Details'!A$2:A$2344,'Hospitalisation Details'!E$2:J$2344)} -> 4-Sep-1963 | N11: 48970.25 | O11: tier - 1 | P11: tier - 2 | Q11: R1013 | R11: 59 | S11: {=_xlfn.IFS(R11<18,"Below 18",R11<=29,"Young Adults",R11<=44,"Adults",R11<=59,"Middle-Aged Adults",R11<=65,"Older Adults",R11>65,"Above 65")} -> Middle-Aged Adults
B12: Id10 | C12: =VLOOKUP(B12,'Customer Names'!A$2:D$2336,3,0) -> Brooke N | D12: {=_xlfn.XLOOKUP(B12,'Medical Examinations'!A$2:A$2336,'Medical Examinations'!B$2:J$2336)} -> 38.06 | E12: 10.79 | F12: No | G12: No | H12: No | I12: 0 | J12: yes | K12: Obesity | L12: Diabetes | M12: {=_xlfn.XLOOKUP(B12,'Hospitalisation Details'!A$2:A$2344,'Hospitalisation Details'!E$2:J$2344)} -> 29-Dec-1978 | N12: 48885.14 | O12: tier - 1 | P12: tier - 2 | Q12: R1013 | R12: 44 | S12: {=_xlfn.IFS(R12<18,"Below 18",R12<=29,"Young Adults",R12<=44,"Adults",R12<=59,"Middle-Aged Adults",R12<=65,"Older Adults",R12>65,"Above 65")} -> Adults
B13: Id11 | C13: =VLOOKUP(B13,'Customer Names'!A$2:D$2336,3,0) -> Paola Andrea | D13: {=_xlfn.XLOOKUP(B13,'Medical Examinations'!A$2:A$2336,'Medical Examinations'!B$2:J$2336)} -> 37.7 | E13: 5.96 | F13: yes | G13: No | H13: No | I13: 2 | J13: yes | K13: Obesity | L13: Pre-Diabetes | M13: {=_xlfn.XLOOKUP(B13,'Hospitalisation Details'!A$2:A$2344,'Hospitalisation Details'!E$2:J$2344)} -> 22-Jul-1959 | N13: 48824.45 | O13: tier - 2 | P13: tier - 1 | Q13: R1011 | R13: 63 | S13: {=_xlfn.IFS(R13<18,"Below 18",R13<=29,"Young Adults",R13<=44,"Adults",R13<=59,"Middle-Aged Adults",R13<=65,"Older Adults",R13>65,"Above 65")} -> Older Adults
B14: Id12 | C14: =VLOOKUP(B14,'Customer Names'!A$2:D$2336,3,0) -> David | D14: {=_xlfn.XLOOKUP(B14,'Medical Examinations'!A$2:A$2336,'Medical Examinations'!B$2:J$2336)} -> 42.13 | E14: 11.9 | F14: No | G14: No | H14: No | I14: 0 | J14: yes | K14: Obesity | L14: Diabetes | M14: {=_xlfn.XLOOKUP(B14,'Hospitalisation Details'!A$2:A$2344,'Hospitalisation Details'!E$2:J$2344)} -> 27-Oct-1965 | N14: 48675.52 | O14: tier - 1 | P14: tier - 2 | Q14: R1013 | R14: 57 | S14: {=_xlfn.IFS(R14<18,"Below 18",R14<=29,"Young Adults",R14<=44,"Adults",R14<=59,"Middle-Aged Adults",R14<=65,"Older Adults",R14>65,"Above 65")} -> Middle-Aged Adults
... B2337: Id2335 | C2337: =VLOOKUP(B2337,'Customer Names'!A$2:D$2336,3,0) -> Aaron K | D2337: {=_xlfn.XLOOKUP(B2337,'Medical Examinations'!A$2:A$2336,'Medical Examinations'!B$2:J$2336)} -> 17.58 | E2337: 4.51 | F2337: No | G2337: No | H2337: No | I2337: 1 | J2337: No | K2337: Underweight | L2337: Normal | M2337: {=_xlfn.XLOOKUP(B2337,'Hospitalisation Details'!A$2:A$2344,'Hospitalisation Details'!E$2:J$2344)} -> 9-Jul-1992 | N2337: 563.84 | O2337: tier - 2 | P2337: tier - 3 | Q2337: R1013 | R2337: 30 | S2337: {=_xlfn.IFS(R2337<18,"Below 18",R2337<=29,"Young Adults",R2337<=44,"Adults",R2337<=59,"Middle-Aged Adults",R2337<=65,"Older Adults",R2337>65,"Above 65")} -> Adults

Sheet pie
A2: 1 | B2: What is the distribution of cancer history among smokers and non-smokers?
B4: Count of Customer ID | C4: Smoke
B5: Cancer History | C5: yes | D5: Grand Total
B6: No | C6: 0.82786885 | D6: 0.82786885
B7: Yes | C7: 0.17213115 | D7: 0.17213115
B8: Grand Total | C8: 1 | D8: 1
B11: Among non smoker
B13: Count of Customer ID | C13: Smoke
B14: Cancer History | C14: No | D14: Grand Total
B15: No | C15: 0.83378452 | D15: 0.83378452
B16: Yes | C16: 0.16621548 | D16: 0.16621548
B17: Grand Total | C17: 1 | D17: 1
A20: 2 | B20: How does the total number of major surgeries and average HbA1C differ between patients with and without a history of transplants?
B24: Count of Customer ID | C24: major surgeries
B25: any transplant? | C25: 0 | D25: 1 | E25: 2 | F25: 3 | G25: Grand Total
B26: No | C26: 1074 | D26: 839 | E26: 256 | F26: 22 | G26: 2191
B27: yes | D27: 126 | E27: 18 | G27: 144
B28: Grand Total | C28: 1074 | D28: 965 | E28: 274 | F28: 22 | G28: 2335
B30: any transplant? | C30: Average of HBA1C
B31: No | C31: 6.6704427
B32: yes | C32: 5.1876389
B33: Grand Total | C33: 6.5789979

Sheet bar
B3: Average of Charges
C4: Diabetes | D4: Normal | E4: Pre-Diabetes | F4: Grand Total
B5: Normal Weight | C5: 14971.472 | D5: 13651.5 | E5: 13969.216 | F5: 14116.596
B6: Obesity | C6: 17727.484 | D6: 14217.079 | E6: 14885.4 | F6: 15723.852
B7: Overweight | C7: 16727.933 | D7: 15213.247 | E7: 15683.634 | F7: 15846.939
B8: Underweight | C8: 8942.6435 | D8: 3935.999 | E8: 4723.7976 | F8: 5097.403
B9: Grand Total | C9: 16120.287 | D9: 12090.723 | E9: 12532.263 | F9: 13529.918
B19: Average of Charges
C20: tier - 1 | D20: tier - 2 | E20: tier - 3 | F20: Grand Total
B21: R1011 | C21: 33081.374 | D21: 18997.281 | E21: 9250.3618 | F21: 19466.246
B22: R1017 | C22: 34070.596 | D22: 11365.622 | E22: 8667.3662 | F22: 14806.108
B23: R1015 | C23: 21523.52 | D23: 15675.543 | E23: 7570.755 | F23: 13948.61
B24: Grand Total | C24: 32951.845 | D24: 18579.525 | E24: 9159.2957 | F24: 19090.078

Sheet Line,scatter
B2: Age Group | C2: Average of Charges
B3: Older Adults | C3: 20886.386
B4: Middle-Aged Adults | C4: 16697.185
B5: Adults | C5: 13261.62
B6: Young Adults | C6: 8770.397
B7: Grand Total | C7: 13529.918
B35: Pearaon correlation | C35: =CORREL(Healthcare!R3:R2337,Healthcare!D3:D2337) -> 0.051869273 | H35: Pearson correlation | I35: =CORREL(Healthcare!R3:R2337,Healthcare!E3:E2337) -> 0.46040821
B36: The correlation is very close to zero, indicating almost no linear relationship between age and BMI in your dataset. | G36: This indicates a moderate positive linear relationship: older patients tend to have higher HbA1C values in your dataset, on average.

Sheet Dashboard
A2: ABC Hospital Healthcare Data Analysis
F6: Average age
D7: 2335 | F7: =AVERAGE(Healthcare!R3:R2337) -> 39.228694

Sheet Interactive Dashboard
