Workbook
Name Slicer_Any_Transplants: #N/A
Name Slicer_Diabetes_Status: #N/A
Name Slicer_smoker: #N/A
Name Slicer_Weight_Status: #N/A

Sheet Customer Names
A1: Customer ID | B1: name
A2: Id1 | B2: Hawks, Ms. Kelly
A3: Id2 | B3: Lehner, Mr. Matthew D
A4: Id3 | B4: Lu, Mr. Phil
A5: Id4 | B5: Osborne, Ms. Kelsey
A6: Id5 | B6: Kadala, Ms. Kristyn
A7: Id6 | B7: Baker, Mr. Russell B.
A8: Id7 | B8: Macpherson, Mr. Scott
A9: Id8 | B9: Hallman, Mr. Stephen
A10: Id9 | B10: Moran, Mr. Patrick R.
A11: Id10 | B11: Benner, Ms. Brooke N.
A12: Id11 | B12: Fierro Vargas, Ms. Paola Andrea
... A2336: Id2335 | B2336: German, Mr. Aaron K

Sheet Medical Examinations
A1: Customer ID | B1: BMI | C1: HBA1C | D1: Heart Issues | E1: Any Transplants | F1: Cancer history | G1: NumberOfMajorSurgeries | H1: smoker
A2: Id1 | B2: 47.41 | C2: 7.47 | D2: No | E2: No | F2: No | G2: No major surgery | H2: yes
A3: Id2 | B3: 30.36 | C3: 5.77 | D3: No | E3: No | F3: No | G3: No major surgery | H3: yes
A4: Id3 | B4: 34.485 | C4: 11.87 | D4: yes | E4: No | F4: No | G4: 2 | H4: yes
A5: Id4 | B5: 38.095 | C5: 6.05 | D5: No | E5: No | F5: No | G5: No major surgery | H5: yes
A6: Id5 | B6: 35.53 | C6: 5.45 | D6: No | E6: No | F6: No | G6: No major surgery | H6: yes
A7: Id6 | B7: 32.8 | C7: 6.59 | D7: No | E7: No | F7: No | G7: No major surgery | H7: yes
A8: Id7 | B8: 36.4 | C8: 6.07 | D8: No | E8: No | F8: No | G8: No major surgery | H8: yes
A9: Id8 | B9: 36.96 | C9: 7.93 | D9: No | E9: No | F9: No | G9: 3 | H9: yes
A10: Id9 | B10: 41.14 | C10: 9.58 | D10: yes | E10: No | F10: Yes | G10: 1 | H10: yes
A11: Id10 | B11: 38.06 | C11: 10.79 | D11: No | E11: No | F11: No | G11: No major surgery | H11: yes
A12: Id11 | B12: 37.7 | C12: 5.96 | D12: yes | E12: No | F12: No | G12: 2 | H12: yes
A13: Id12 | B13: 42.13 | C13: 11.9 | D13: No | E13: No | F13: No | G13: No major surgery | H13: yes
A14: Id13 | B14: 40.92 | C14: 8.41 | D14: No | E14: No | F14: No | G14: No major surgery | H14: yes
A15: Id14 | B15: 40.565 | C15: 7.02 | D15: No | E15: No | F15: No | G15: No major surgery | H15: yes
A16: Id15 | B16: 36.385 | C16: 7.59 | D16: yes | E16: No | F16: No | G16: 2 | H16: yes
A17: Id16 | B17: 39.9 | C17: 11.32 | D17: No | E17: No | F17: No | G17: No major surgery | H17: yes
A18: Id17 | B18: 33.8 | C18: 7.67 | D18: No | E18: No | F18: No | G18: 3 | H18: yes
A19: Id18 | B19: 36.765 | C19: 7.29 | D19: yes | E19: No | F19: Yes | G19: 1 | H19: yes
A20: Id19 | B20: 36.955 | C20: 4.72 | D20: yes | E20: No | F20: No | G20: 1 | H20: yes
A21: Id20 | B21: 42.9 | C21: 11.41 | D21: No | E21: No | F21: No | G21: No major surgery | H21: yes
A22: Id21 | B22: 36.3 | C22: 11.5 | D22: yes | E22: No | F22: No | G22: 2 | H22: yes
A23: Id22 | B23: 32.2 | C23: 6.22 | D23: yes | E23: No | F23: No | G23: 2 | H23: yes
A24: Id23 | B24: 31.3 | C24: 11.38 | D24: No | E24: No | F24: No | G24: 3 | H24: yes
A25: Id24 | B25: 41.8 | C25: 7.89 | D25: yes | E25: No | F25: No | G25: 2 | H25: yes
A26: Id25 | B26: 35.09 | C26: 4.38 | D26: yes | E26: No | F26: No | G26: 2 | H26: yes
A27: Id26 | B27: 33.88 | C27: 7.01 | D27: No | E27: No | F27: No | G27: 3 | H27: yes
A28: Id27 | B28: 30.875 | C28: 11.88 | D28: No | E28: No | F28: No | G28: No major surgery | H28: yes
A29: Id28 | B29: 36.86 | C29: 5.19 | D29: yes | E29: No | F29: Yes | G29: 1 | H29: yes
A30: Id29 | B30: 35.86 | C30: 6.74 | D30: yes | E30: No | F30: No | G30: 2 | H30: yes
A31: Id30 | B31: 37.05 | C31: 8.44 | D31: No | E31: No | F31: No | G31: No major surgery | H31: yes
A32: Id31 | B32: 43.89 | C32: 8.71 | D32: No | E32: No | F32: No | G32: No major surgery | H32: yes
A33: Id32 | B33: 42.35 | C33: 5.08 | D33: yes | E33: No | F33: No | G33: No major surgery | H33: yes
A34: Id33 | B34: 31.35 | C34: 6.86 | D34: No | E34: No | F34: No | G34: No major surgery | H34: yes
A35: Id34 | B35: 47.6 | C35: 5.95 | D35: yes | E35: No | F35: No | G35: No major surgery | H35: yes
A36: Id35 | B36: 46.2 | C36: 6.09 | D36: No | E36: No | F36: Yes | G36: 1 | H36: yes
A37: Id36 | B37: 32.015 | C37: 11.75 | D37: No | E37: No | F37: No | G37: No major surgery | H37: yes
A38: Id37 | B38: 40.565 | C38: 7.37 | D38: No | E38: No | F38: No | G38: No major surgery | H38: yes
A39: Id38 | B39: 32.45 | C39: 11.91 | D39: No | E39: No | F39: No | G39: No major surgery | H39: yes
A40: Id39 | B40: 34.96 | C40: 6.52 | D40: No | E40: No | F40: No | G40: No major surgery | H40: yes
...

Sheet Hospitalisation Details
A1: Customer ID | B1: year | C1: month | D1: date | E1: children | F1: charges | G1: Hospital tier | H1: City tier | I1: State ID
A2: Id2335 | B2: 1992 | C2: Jul | D2: 9 | E2: 0 | F2: 563.84 | G2: tier - 2 | H2: tier - 3 | I2: R1013
A3: Id2334 | B3: 1992 | C3: Nov | D3: 30 | E3: 0 | F3: 570.62 | G3: tier - 2 | H3: tier - 1 | I3: R1013
A4: Id2333 | B4: 1993 | C4: Jun | D4: 30 | E4: 0 | F4: 600 | G4: tier - 2 | H4: tier - 1 | I4: R1013
A5: Id2332 | B5: 1992 | C5: Sep | D5: 13 | E5: 0 | F5: 604.54 | G5: tier - 3 | H5: tier - 3 | I5: R1013
A6: Id2331 | B6: 1998 | C6: Jul | D6: 27 | E6: 0 | F6: 637.26 | G6: tier - 3 | H6: tier - 3 | I6: R1013
A7: Id2330 | B7: 2001 | C7: Nov | D7: 20 | E7: 0 | F7: 646.14 | G7: tier - 3 | H7: tier - 3 | I7: R1012
A8: Id2329 | B8: 1993 | C8: Jun | D8: 1 | E8: 0 | F8: 650 | G8: tier - 3 | H8: tier - 3 | I8: R1013
A9: Id2328 | B9: 1995 | C9: Jul | D9: 4 | E9: 0 | F9: 650 | G9: tier - 3 | H9: tier - 3 | I9: R1013
A10: Id2327 | B10: 2002 | C10: Nov | D10: 29 | E10: 0 | F10: 668 | G10: tier - 3 | H10: tier - 2 | I10: R1012
A11: Id2326 | B11: 1997 | C11: Nov | D11: 9 | E11: 0 | F11: 670 | G11: tier - 3 | H11: tier - 3 | I11: R1013
A12: Id2325 | B12: 2001 | C12: Sep | D12: 12 | E12: 0 | F12: 687.54 | G12: tier - 3 | H12: tier - 2 | I12: R1013
A13: Id2324 | B13: 1999 | C13: Dec | D13: 26 | E13: 0 | F13: 700 | G13: ? | H13: tier - 3 | I13: R1013
... A1050: Id1290 | B1050: 1977 | C1050: Jul | D1050: 26 | E1050: 2 | F1050: 8527.53 | G1050: tier - 2 | H1050: tier - 2 | I1050: R1013
A1051: Id1289 | B1051: ? | C1051: Jul | D1051: 24 | E1051: 0 | F1051: 8534.67 | G1051: tier - 2 | H1051: tier - 3 | I1051: R1024
A1052: Id1288 | B1052: 1981 | C1052: Dec | D1052: 27 | E1052: 3 | F1052: 8538.29 | G1052: tier - 2 | H1052: tier - 3 | I1052: R1024
A1053: Id1287 | B1053: 1975 | C1053: Nov | D1053: 6 | E1053: 1 | F1053: 8539.67 | G1053: tier - 2 | H1053: tier - 3 | I1053: R1011
A1054: Id1286 | B1054: ? | C1054: Dec | D1054: 12 | E1054: 1 | F1054: 8547.69 | G1054: tier - 2 | H1054: tier - 1 | I1054: R1013
A1055: Id1285 | B1055: 1975 | C1055: Aug | D1055: 6 | E1055: 1 | F1055: 8551.35 | G1055: tier - 2 | H1055: tier - 2 | I1055: R1011
A1056: Id1284 | B1056: 1975 | C1056: Aug | D1056: 21 | E1056: 1 | F1056: 8556.91 | G1056: tier - 2 | H1056: tier - 1 | I1056: R1011
A1057: Id1283 | B1057: 1988 | C1057: Sep | D1057: 21 | E1057: 3 | F1057: 8567.25 | G1057: tier - 2 | H1057: tier - 1 | I1057: R1012
A1058: Id1282 | B1058: 1975 | C1058: Sep | D1058: 26 | E1058: 1 | F1058: 8569.86 | G1058: tier - 2 | H1058: tier - 3 | I1058: R1013
A1059: Id1281 | B1059: 1982 | C1059: Dec | D1059: 6 | E1059: 3 | F1059: 8572.04 | G1059: tier - 2 | H1059: tier - 2 | I1059: R1021
A1060: Id1280 | B1060: 1987 | C1060: Nov | D1060: 11 | E1060: 3 | F1060: 8573.3 | G1060: tier - 2 | H1060: tier - 2 | I1060: R1021
A1061: Id1279 | B1061: 1983 | C1061: Dec | D1061: 30 | E1061: 5 | F1061: 8582.3 | G1061: tier - 2 | H1061: tier - 1 | I1061: R1013
A1062: Id1278 | B1062: 1983 | C1062: Jul | D1062: 25 | E1062: 5 | F1062: 8596.83 | G1062: tier - 2 | H1062: tier - 3 | I1062: R1013
A1063: Id1277 | B1063: 1973 | C1063: Jul | D1063: 11 | E1063: 0 | F1063: 8601.33 | G1063: tier - 2 | H1063: tier - 1 | I1063: R1013
A1064: Id1276 | B1064: 1977 | C1064: Sep | D1064: 24 | E1064: 2 | F1064: 8603.82 | G1064: tier - 2 | H1064: tier - 1 | I1064: R1019
A1065: Id1275 | B1065: 1977 | C1065: Nov | D1065: 12 | E1065: 2 | F1065: 8604.48 | G1065: tier - 3 | H1065: tier - 2 | I1065: R1016
A1066: Id1274 | B1066: 1977 | C1066: Oct | D1066: 15 | E1066: 3 | F1066: 8605.36 | G1066: tier - 2 | H1066: tier - 2 | I1066: R1013
... A2344: Id1 | B2344: 1968 | C2344: Oct | D2344: 12 | E2344: 0 | F2344: 63770.43 | G2344: tier - 1 | H2344: tier - 3 | I2344: R1013

Sheet Data cleaning 1.
A2: Customer ID | B2: BMI | C2: HBA1C | D2: Heart Issues | E2: Any Transplants | F2: Cancer history | G2: NumberOfMajorSurgeries | H2: smoker
A3: Id1 | B3: 47.41 | C3: 7.47 | D3: No | E3: No | F3: No | G3: No major surgery | H3: yes
A4: Id2 | B4: 30.36 | C4: 5.77 | D4: No | E4: No | F4: No | G4: No major surgery | H4: yes
A5: Id3 | B5: 34.485 | C5: 11.87 | D5: yes | E5: No | F5: No | G5: 2 | H5: yes | J5: Number of missing values '?'
A6: Id4 | B6: 38.095 | C6: 6.05 | D6: No | E6: No | F6: No | G6: No major surgery | H6: yes
A7: Id5 | B7: 35.53 | C7: 5.45 | D7: No | E7: No | F7: No | G7: No major surgery | H7: yes | J7: Customer ID | K7: =COUNTIF(A3:A2337,"?") -> 0
A8: Id6 | B8: 32.8 | C8: 6.59 | D8: No | E8: No | F8: No | G8: No major surgery | H8: yes | J8: BMI | K8: =COUNTIF(B3:B2337,"?") -> 0
A9: Id7 | B9: 36.4 | C9: 6.07 | D9: No | E9: No | F9: No | G9: No major surgery | H9: yes | J9: HBA1C | K9: =COUNTIF(C3:C2337,"?") -> 0
A10: Id8 | B10: 36.96 | C10: 7.93 | D10: No | E10: No | F10: No | G10: 3 | H10: yes | J10: Heart Issues | K10: =COUNTIF(D3:D2337,"?") -> 0
A11: Id9 | B11: 41.14 | C11: 9.58 | D11: yes | E11: No | F11: Yes | G11: 1 | H11: yes | J11: Any Transplants | K11: =COUNTIF(E3:E2337,"?") -> 0
A12: Id10 | B12: 38.06 | C12: 10.79 | D12: No | E12: No | F12: No | G12: No major surgery | H12: yes | J12: Cancer history | K12: =COUNTIF(F3:F2337,"?") -> 0
A13: Id11 | B13: 37.7 | C13: 5.96 | D13: yes | E13: No | F13: No | G13: 2 | H13: yes | J13: NumberOfMajorSurgeries | K13: =COUNTIF(G3:G2337,"?") -> 0
A14: Id12 | B14: 42.13 | C14: 11.9 | D14: No | E14: No | F14: No | G14: No major surgery | H14: yes | J14: smoker | K14: =COUNTIF(H3:H2337,"?") -> 0
A15: Id13 | B15: 40.92 | C15: 8.41 | D15: No | E15: No | F15: No | G15: No major surgery | H15: yes
A16: Id14 | B16: 40.565 | C16: 7.02 | D16: No | E16: No | F16: No | G16: No major surgery | H16: yes
A17: Id15 | B17: 36.385 | C17: 7.59 | D17: yes | E17: No | F17: No | G17: 2 | H17: yes | J17: Most frequently occuring value in smoker
A18: Id16 | B18: 39.9 | C18: 11.32 | D18: No | E18: No | F18: No | G18: No major surgery | H18: yes
A19: Id17 | B19: 33.8 | C19: 7.67 | D19: No | E19: No | F19: No | G19: 3 | H19: yes | J19: yes | K19: =COUNTIF(H$3:H$2337,J19) -> 488
A20: Id18 | B20: 36.765 | C20: 7.29 | D20: yes | E20: No | F20: Yes | G20: 1 | H20: yes | J20: No | K20: =COUNTIF(H$3:H$2337,J20) -> 1847
A21: Id19 | B21: 36.955 | C21: 4.72 | D21: yes | E21: No | F21: No | G21: 1 | H21: yes
A22: Id20 | B22: 42.9 | C22: 11.41 | D22: No | E22: No | F22: No | G22: No major surgery | H22: yes
A23: Id21 | B23: 36.3 | C23: 11.5 | D23: yes | E23: No | F23: No | G23: 2 | H23: yes
A24: Id22 | B24: 32.2 | C24: 6.22 | D24: yes | E24: No | F24: No | G24: 2 | H24: yes
A25: Id23 | B25: 31.3 | C25: 11.38 | D25: No | E25: No | F25: No | G25: 3 | H25: yes
A26: Id24 | B26: 41.8 | C26: 7.89 | D26: yes | E26: No | F26: No | G26: 2 | H26: yes
A27: Id25 | B27: 35.09 | C27: 4.38 | D27: yes | E27: No | F27: No | G27: 2 | H27: yes
A28: Id26 | B28: 33.88 | C28: 7.01 | D28: No | E28: No | F28: No | G28: 3 | H28: yes
A29: Id27 | B29: 30.875 | C29: 11.88 | D29: No | E29: No | F29: No | G29: No major surgery | H29: yes
A30: Id28 | B30: 36.86 | C30: 5.19 | D30: yes | E30: No | F30: Yes | G30: 1 | H30: yes
A31: Id29 | B31: 35.86 | C31: 6.74 | D31: yes | E31: No | F31: No | G31: 2 | H31: yes
A32: Id30 | B32: 37.05 | C32: 8.44 | D32: No | E32: No | F32: No | G32: No major surgery | H32: yes
A33: Id31 | B33: 43.89 | C33: 8.71 | D33: No | E33: No | F33: No | G33: No major surgery | H33: yes
A34: Id32 | B34: 42.35 | C34: 5.08 | D34: yes | E34: No | F34: No | G34: No major surgery | H34: yes
A35: Id33 | B35: 31.35 | C35: 6.86 | D35: No | E35: No | F35: No | G35: No major surgery | H35: yes
A36: Id34 | B36: 47.6 | C36: 5.95 | D36: yes | E36: No | F36: No | G36: No major surgery | H36: yes
A37: Id35 | B37: 46.2 | C37: 6.09 | D37: No | E37: No | F37: Yes | G37: 1 | H37: yes
A38: Id36 | B38: 32.015 | C38: 11.75 | D38: No | E38: No | F38: No | G38: No major surgery | H38: yes
A39: Id37 | B39: 40.565 | C39: 7.37 | D39: No | E39: No | F39: No | G39: No major surgery | H39: yes
A40: Id38 | B40: 32.45 | C40: 11.91 | D40: No | E40: No | F40: No | G40: No major surgery | H40: yes
A41: Id39 | B41: 34.96 | C41: 6.52 | D41: No | E41: No | F41: No | G41: No major surgery | H41: yes
...

Sheet Data cleaning 2
A2: Customer ID | B2: year | C2: month | D2: date | E2: children | F2: charges | G2: Hospital tier | H2: City tier | I2: State ID
A3: Id2335 | B3: 1992 | C3: Jul | D3: 9 | E3: 0 | F3: 563.84 | G3: tier - 2 | H3: tier - 3 | I3: R1013
A4: Id2334 | B4: 1992 | C4: Nov | D4: 30 | E4: 0 | F4: 570.62 | G4: tier - 2 | H4: tier - 1 | I4: R1013 | L4: Number of missing values | P4: Most frequently occuring values
A5: Id2333 | B5: 1993 | C5: Jun | D5: 30 | E5: 0 | F5: 600 | G5: tier - 2 | H5: tier - 1 | I5: R1013
A6: Id2332 | B6: 1992 | C6: Sep | D6: 13 | E6: 0 | F6: 604.54 | G6: tier - 3 | H6: tier - 3 | I6: R1013 | L6: Customer ID | M6: =COUNTIF(A3:A2345,"?") -> 6 | P6: Hospital tier
A7: Id2331 | B7: 1998 | C7: Jul | D7: 27 | E7: 0 | F7: 637.26 | G7: tier - 3 | H7: tier - 3 | I7: R1013 | L7: year | M7: =COUNTIF(B3:B2345,"?") -> 0 | P7: tier - 1 | Q7: =COUNTIF(G$3:G$2345,P7) -> 309
A8: Id2330 | B8: 2001 | C8: Nov | D8: 20 | E8: 0 | F8: 646.14 | G8: tier - 3 | H8: tier - 3 | I8: R1012 | L8: month | M8: =COUNTIF(C3:C2345,"?") -> 0 | P8: tier - 2 | Q8: =COUNTIF(G$3:G$2345,P8) -> 1340
A9: Id2329 | B9: 1993 | C9: Jun | D9: 1 | E9: 0 | F9: 650 | G9: tier - 3 | H9: tier - 3 | I9: R1013 | L9: date | M9: =COUNTIF(D3:D2345,"?") -> 0 | P9: tier - 3 | Q9: =COUNTIF(G$3:G$2345,P9) -> 694
A10: Id2328 | B10: 1995 | C10: Jul | D10: 4 | E10: 0 | F10: 650 | G10: tier - 3 | H10: tier - 3 | I10: R1013 | L10: children | M10: =COUNTIF(E3:E2345,"?") -> 0
A11: Id2327 | B11: 2002 | C11: Nov | D11: 29 | E11: 0 | F11: 668 | G11: tier - 3 | H11: tier - 2 | I11: R1012 | L11: charges | M11: =COUNTIF(F3:F2345,"?") -> 0 | P11: City tier
A12: Id2326 | B12: 1997 | C12: Nov | D12: 9 | E12: 0 | F12: 670 | G12: tier - 3 | H12: tier - 3 | I12: R1013 | L12: Hospital tier | M12: =COUNTIF(G3:G2345,"?") -> 0 | P12: tier - 1 | Q12: =COUNTIF(H$3:H$2345,P12) -> 734
A13: Id2325 | B13: 2001 | C13: Sep | D13: 12 | E13: 0 | F13: 687.54 | G13: tier - 3 | H13: tier - 2 | I13: R1013 | L13: City tier | M13: =COUNTIF(H3:H2345,"?") -> 0 | P13: tier - 2 | Q13: =COUNTIF(H$3:H$2345,P13) -> 813
A14: Id2324 | B14: 1999 | C14: Dec | D14: 26 | E14: 0 | F14: 700 | G14: tier - 2 | H14: tier - 3 | I14: R1013 | L14: State ID | M14: =COUNTIF(I3:I2345,"?") -> 0 | P14: tier - 3 | Q14: =COUNTIF(H$3:H$2345,P14) -> 796
A15: Id2323 | B15: 1999 | C15: Dec | D15: 14 | E15: 0 | F15: 722.99 | G15: tier - 3 | H15: tier - 1 | I15: R1013
A16: Id2322 | B16: 2002 | C16: Sep | D16: 19 | E16: 0 | F16: 750 | G16: tier - 3 | H16: tier - 1 | I16: R1012
A17: Id2321 | B17: 1993 | C17: Aug | D17: 9 | E17: 0 | F17: 760 | G17: tier - 3 | H17: tier - 1 | I17: R1013 | L17: Fill in missing values with "Sep"
A18: Id2320 | B18: 1996 | C18: Oct | D18: 22 | E18: 0 | F18: 760 | G18: tier - 3 | H18: tier - 3 | I18: R1013 | L18: Filter --> select ? --> replace with Sep
A19: Id2319 | B19: 1993 | C19: Jun | D19: 28 | E19: 0 | F19: 770 | G19: tier - 3 | H19: tier - 3 | I19: R1013
A20: Id2318 | B20: 1996 | C20: Sep | D20: 18 | E20: 0 | F20: 770.38 | G20: tier - 3 | H20: tier - 2 | I20: R1012 | L20: Fill in missing year with average year rounded to nearest integer
A21: Id2317 | B21: 1995 | C21: Dec | D21: 7 | E21: 0 | F21: 773.54 | G21: tier - 3 | H21: tier - 2 | I21: R1013 | L21: =AVERAGE(B3:B2345) -> 1982.8417
A22: Id2316 | B22: 2004 | C22: Oct | D22: 7 | E22: 0 | F22: 830.52 | G22: tier - 3 | H22: tier - 2 | I22: R1011
A23: Id2315 | B23: 2000 | C23: Nov | D23: 18 | E23: 0 | F23: 865.41 | G23: tier - 3 | H23: tier - 1 | I23: R1013 | L23: Missing State IDs replaced with "Unknown"
A24: Id2314 | B24: 1993 | C24: Nov | D24: 27 | E24: 0 | F24: 896.21 | G24: tier - 3 | H24: tier - 1 | I24: R1013
A25: Id2313 | B25: 1994 | C25: Oct | D25: 30 | E25: 0 | F25: 915.07 | G25: tier - 3 | H25: tier - 1 | I25: R1013
A26: Id2312 | B26: 1995 | C26: Oct | D26: 28 | E26: 0 | F26: 928.59 | G26: tier - 3 | H26: tier - 1 | I26: R1013
A27: Id2311 | B27: 2001 | C27: Aug | D27: 19 | E27: 0 | F27: 964.71 | G27: tier - 3 | H27: tier - 2 | I27: R1013
A28: Id2310 | B28: 1994 | C28: Nov | D28: 22 | E28: 0 | F28: 1006.65 | G28: tier - 3 | H28: tier - 2 | I28: R1013
A29: Id2309 | B29: 2000 | C29: Oct | D29: 9 | E29: 0 | F29: 1012 | G29: tier - 3 | H29: tier - 2 | I29: R1013
A30: Id2308 | B30: 1999 | C30: Aug | D30: 5 | E30: 0 | F30: 1019 | G30: tier - 3 | H30: tier - 2 | I30: R1013
A31: Id2307 | B31: 1995 | C31: Oct | D31: 5 | E31: 0 | F31: 1033.74 | G31: tier - 3 | H31: tier - 1 | I31: R1013
A32: Id2306 | B32: 1994 | C32: Nov | D32: 17 | E32: 0 | F32: 1044 | G32: tier - 3 | H32: tier - 2 | I32: R1013
A33: Id2305 | B33: 2002 | C33: Jul | D33: 20 | E33: 0 | F33: 1047 | G33: tier - 3 | H33: tier - 1 | I33: R1013
A34: Id2304 | B34: 2002 | C34: Jul | D34: 1 | E34: 0 | F34: 1049 | G34: tier - 3 | H34: tier - 2 | I34: R1012
A35: Id2303 | B35: 1995 | C35: Jun | D35: 1 | E35: 0 | F35: 1056 | G35: tier - 3 | H35: tier - 2 | I35: R1013
... A2345: Id1 | B2345: 1968 | C2345: Oct | D2345: 12 | E2345: 0 | F2345: 63770.43 | G2345: tier - 1 | H2345: tier - 3 | I2345: R1013

Sheet Data Transformation 1.
A2: Customer ID | B2: First Name | C2: Title | D2: Last Name
A3: Id1 | B3: Kelly | C3: Ms | D3: Hawks
A4: Id2 | B4: Matthew D | C4: Mr | D4: Lehner
A5: Id3 | B5: Phil | C5: Mr | D5: Lu | H5: Split name to Title, first name, last name
A6: Id4 | B6: Kelsey | C6: Ms | D6: Osborne | H6: done using text to column - delimeter - ,
A7: Id5 | B7: Kristyn | C7: Ms | D7: Kadala | H7: done using text to column - delimeter - .
A8: Id6 | B8: Russell B | C8: Mr | D8: Baker
A9: Id7 | B9: Scott | C9: Mr | D9: Macpherson
A10: Id8 | B10: Stephen | C10: Mr | D10: Hallman
A11: Id9 | B11: Patrick R | C11: Mr | D11: Moran
A12: Id10 | B12: Brooke N | C12: Ms | D12: Benner
A13: Id11 | B13: Paola Andrea | C13: Ms | D13: Fierro Vargas
A14: Id12 | B14: David | C14: Mr | D14: Franz
A15: Id13 | B15: Wade | C15: Mr | D15: Foster
A16: Id14 | B16: Franklin | C16: Mr | D16: Tenorio
A17: Id15 | B17: Leilani M | C17: Ms | D17: Rios
A18: Id16 | B18: Philippe | C18: Mr | D18: Viau-Dupuis
A19: Id17 | B19: Jennifer A | C19: Ms | D19: Cronin
... A73: Id71 | B73: Jeff | C73: Mr | D73: Turner
A74: Id72 | B74: Elenilton V | C74: Mr | D74: Rangel | G74: Sr
A75: Id73 | B75: Maurya | C75: Ms | D75: Lacey
A76: Id74 | B76: Samantha C | C76: Ms | D76: Stiger
A77: Id75 | B77: Bethany A | C77: Ms | D77: Caldwell
A78: Id76 | B78: Yves | C78: Mr | D78: Marmillod
A79: Id77 | B79: Danielle | C79: Ms | D79: Cloutier-Simons
A80: Id78 | B80: Julia | C80: Ms | D80: Vegas
A81: Id79 | B81: Joshua | C81: Mr | D81: Cochran
A82: Id80 | B82: Jennifer | C82: Ms | D82: Holtzapple
A83: Id81 | B83: Gwen M | C83: Ms | D83: Meyer
A84: Id82 | B84: Patrick | C84: Mr | D84: Brickley
A85: Id83 | B85: Kate | C85: Ms | D85: Magee
A86: Id84 | B86: Kevin | C86: Mr | D86: Thoma
... A189: Id187 | B189: Andrew P | C189: Mr | D189: Dublin
A190: Id188 | B190: George M | C190: Mr | D190: Cleland | G190: V
A191: Id189 | B191: Sarah | C191: Ms | D191: Evans
A192: Id190 | B192: Lara | C192: Ms | D192: Boyd
A193: Id191 | B193: Sebastien | C193: Mr | D193: Roulier
A194: Id192 | B194: Padraig | C194: Mr | D194: Mullins
A195: Id193 | B195: Heather | C195: Ms | D195: Hofmann
A196: Id194 | B196: Jorge | C196: Mr | D196: Garcia Garcia
...

Sheet Data transformation 2
A2: Customer ID | B2: BMI | C2: HBA1C | D2: Heart Issues | E2: Any Transplants | F2: Cancer history | G2: NumberOfMajorSurgeries | H2: smoker | I2: Weight Status | J2: Diabetes Status
A3: Id1 | B3: 47.41 | C3: 7.47 | D3: No | E3: No | F3: No | G3: 0 | H3: yes | I3: {=_xlfn.IFS(B3<18.5,"Underweight",B3<25,"Normal Weight",B3<30,"Overweight",B3>=30,"Obesity")} -> Obesity | J3: {=_xlfn.IFS(C3<5.7,"Normal",C3<6.5,"Pre-Diabetes",C3>=6.5,"Diabetes")} -> Diabetes
A4: Id2 | B4: 30.36 | C4: 5.77 | D4: No | E4: No | F4: No | G4: 0 | H4: yes | I4: {=_xlfn.IFS(B4<18.5,"Underweight",B4<25,"Normal Weight",B4<30,"Overweight",B4>=30,"Obesity")} -> Obesity | J4: {=_xlfn.IFS(C4<5.7,"Normal",C4<6.5,"Pre-Diabetes",C4>=6.5,"Diabetes")} -> Pre-Diabetes
A5: Id3 | B5: 34.485 | C5: 11.87 | D5: yes | E5: No | F5: No | G5: 2 | H5: yes | I5: {=_xlfn.IFS(B5<18.5,"Underweight",B5<25,"Normal Weight",B5<30,"Overweight",B5>=30,"Obesity")} -> Obesity | J5: {=_xlfn.IFS(C5<5.7,"Normal",C5<6.5,"Pre-Diabetes",C5>=6.5,"Diabetes")} -> Diabetes
A6: Id4 | B6: 38.095 | C6: 6.05 | D6: No | E6: No | F6: No | G6: 0 | H6: yes | I6: {=_xlfn.IFS(B6<18.5,"Underweight",B6<25,"Normal Weight",B6<30,"Overweight",B6>=30,"Obesity")} -> Obesity | J6: {=_xlfn.IFS(C6<5.7,"Normal",C6<6.5,"Pre-Diabetes",C6>=6.5,"Diabetes")} -> Pre-Diabetes
A7: Id5 | B7: 35.53 | C7: 5.45 | D7: No | E7: No | F7: No | G7: 0 | H7: yes | I7: {=_xlfn.IFS(B7<18.5,"Underweight",B7<25,"Normal Weight",B7<30,"Overweight",B7>=30,"Obesity")} -> Obesity | J7: {=_xlfn.IFS(C7<5.7,"Normal",C7<6.5,"Pre-Diabetes",C7>=6.5,"Diabetes")} -> Normal
A8: Id6 | B8: 32.8 | C8: 6.59 | D8: No | E8: No | F8: No | G8: 0 | H8: yes | I8: {=_xlfn.IFS(B8<18.5,"Underweight",B8<25,"Normal Weight",B8<30,"Overweight",B8>=30,"Obesity")} -> Obesity | J8: {=_xlfn.IFS(C8<5.7,"Normal",C8<6.5,"Pre-Diabetes",C8>=6.5,"Diabetes")} -> Diabetes
A9: Id7 | B9: 36.4 | C9: 6.07 | D9: No | E9: No | F9: No | G9: 0 | H9: yes | I9: {=_xlfn.IFS(B9<18.5,"Underweight",B9<25,"Normal Weight",B9<30,"Overweight",B9>=30,"Obesity")} -> Obesity | J9: {=_xlfn.IFS(C9<5.7,"Normal",C9<6.5,"Pre-Diabetes",C9>=6.5,"Diabetes")} -> Pre-Diabetes | L9: Convert non-numeric data to numeric value in number of surgeries column
A10: Id8 | B10: 36.96 | C10: 7.93 | D10: No | E10: No | F10: No | G10: 3 | H10: yes | I10: {=_xlfn.IFS(B10<18.5,"Underweight",B10<25,"Normal Weight",B10<30,"Overweight",B10>=30,"Obesity")} -> Obesity | J10: {=_xlfn.IFS(C10<5.7,"Normal",C10<6.5,"Pre-Diabetes",C10>=6.5,"Diabetes")} -> Diabetes | L10: Replaced with 0 using Find and Replace
A11: Id9 | B11: 41.14 | C11: 9.58 | D11: yes | E11: No | F11: Yes | G11: 1 | H11: yes | I11: {=_xlfn.IFS(B11<18.5,"Underweight",B11<25,"Normal Weight",B11<30,"Overweight",B11>=30,"Obesity")} -> Obesity | J11: {=_xlfn.IFS(C11<5.7,"Normal",C11<6.5,"Pre-Diabetes",C11>=6.5,"Diabetes")} -> Diabetes
A12: Id10 | B12: 38.06 | C12: 10.79 | D12: No | E12: No | F12: No | G12: 0 | H12: yes | I12: {=_xlfn.IFS(B12<18.5,"Underweight",B12<25,"Normal Weight",B12<30,"Overweight",B12>=30,"Obesity")} -> Obesity | J12: {=_xlfn.IFS(C12<5.7,"Normal",C12<6.5,"Pre-Diabetes",C12>=6.5,"Diabetes")} -> Diabetes | L12: Categorized BMI to different weight statuses
A13: Id11 | B13: 37.7 | C13: 5.96 | D13: yes | E13: No | F13: No | G13: 2 | H13: yes | I13: {=_xlfn.IFS(B13<18.5,"Underweight",B13<25,"Normal Weight",B13<30,"Overweight",B13>=30,"Obesity")} -> Obesity | J13: {=_xlfn.IFS(C13<5.7,"Normal",C13<6.5,"Pre-Diabetes",C13>=6.5,"Diabetes")} -> Pre-Diabetes | L13: using IFS
A14: Id12 | B14: 42.13 | C14: 11.9 | D14: No | E14: No | F14: No | G14: 0 | H14: yes | I14: {=_xlfn.IFS(B14<18.5,"Underweight",B14<25,"Normal Weight",B14<30,"Overweight",B14>=30,"Obesity")} -> Obesity | J14: {=_xlfn.IFS(C14<5.7,"Normal",C14<6.5,"Pre-Diabetes",C14>=6.5,"Diabetes")} -> Diabetes
A15: Id13 | B15: 40.92 | C15: 8.41 | D15: No | E15: No | F15: No | G15: 0 | H15: yes | I15: {=_xlfn.IFS(B15<18.5,"Underweight",B15<25,"Normal Weight",B15<30,"Overweight",B15>=30,"Obesity")} -> Obesity | J15: {=_xlfn.IFS(C15<5.7,"Normal",C15<6.5,"Pre-Diabetes",C15>=6.5,"Diabetes")} -> Diabetes | L15: Categorized HBA1C to different weight statuses
A16: Id14 | B16: 40.565 | C16: 7.02 | D16: No | E16: No | F16: No | G16: 0 | H16: yes | I16: {=_xlfn.IFS(B16<18.5,"Underweight",B16<25,"Normal Weight",B16<30,"Overweight",B16>=30,"Obesity")} -> Obesity | J16: {=_xlfn.IFS(C16<5.7,"Normal",C16<6.5,"Pre-Diabetes",C16>=6.5,"Diabetes")} -> Diabetes | L16: usinf IFS
A17: Id15 | B17: 36.385 | C17: 7.59 | D17: yes | E17: No | F17: No | G17: 2 | H17: yes | I17: {=_xlfn.IFS(B17<18.5,"Underweight",B17<25,"Normal Weight",B17<30,"Overweight",B17>=30,"Obesity")} -> Obesity | J17: {=_xlfn.IFS(C17<5.7,"Normal",C17<6.5,"Pre-Diabetes",C17>=6.5,"Diabetes")} -> Diabetes
A18: Id16 | B18: 39.9 | C18: 11.32 | D18: No | E18: No | F18: No | G18: 0 | H18: yes | I18: {=_xlfn.IFS(B18<18.5,"Underweight",B18<25,"Normal Weight",B18<30,"Overweight",B18>=30,"Obesity")} -> Obesity | J18: {=_xlfn.IFS(C18<5.7,"Normal",C18<6.5,"Pre-Diabetes",C18>=6.5,"Diabetes")} -> Diabetes
A19: Id17 | B19: 33.8 | C19: 7.67 | D19: No | E19: No | F19: No | G19: 3 | H19: yes | I19: {=_xlfn.IFS(B19<18.5,"Underweight",B19<25,"Normal Weight",B19<30,"Overweight",B19>=30,"Obesity")} -> Obesity | J19: {=_xlfn.IFS(C19<5.7,"Normal",C19<6.5,"Pre-Diabetes",C19>=6.5,"Diabetes")} -> Diabetes
A20: Id18 | B20: 36.765 | C20: 7.29 | D20: yes | E20: No | F20: Yes | G20: 1 | H20: yes | I20: {=_xlfn.IFS(B20<18.5,"Underweight",B20<25,"Normal Weight",B20<30,"Overweight",B20>=30,"Obesity")} -> Obesity | J20: {=_xlfn.IFS(C20<5.7,"Normal",C20<6.5,"Pre-Diabetes",C20>=6.5,"Diabetes")} -> Diabetes
A21: Id19 | B21: 36.955 | C21: 4.72 | D21: yes | E21: No | F21: No | G21: 1 | H21: yes | I21: {=_xlfn.IFS(B21<18.5,"Underweight",B21<25,"Normal Weight",B21<30,"Overweight",B21>=30,"Obesity")} -> Obesity | J21: {=_xlfn.IFS(C21<5.7,"Normal",C21<6.5,"Pre-Diabetes",C21>=6.5,"Diabetes")} -> Normal
A22: Id20 | B22: 42.9 | C22: 11.41 | D22: No | E22: No | F22: No | G22: 0 | H22: yes | I22: {=_xlfn.IFS(B22<18.5,"Underweight",B22<25,"Normal Weight",B22<30,"Overweight",B22>=30,"Obesity")} -> Obesity | J22: {=_xlfn.IFS(C22<5.7,"Normal",C22<6.5,"Pre-Diabetes",C22>=6.5,"Diabetes")} -> Diabetes
A23: Id21 | B23: 36.3 | C23: 11.5 | D23: yes | E23: No | F23: No | G23: 2 | H23: yes | I23: {=_xlfn.IFS(B23<18.5,"Underweight",B23<25,"Normal Weight",B23<30,"Overweight",B23>=30,"Obesity")} -> Obesity | J23: {=_xlfn.IFS(C23<5.7,"Normal",C23<6.5,"Pre-Diabetes",C23>=6.5,"Diabetes")} -> Diabetes
A24: Id22 | B24: 32.2 | C24: 6.22 | D24: yes | E24: No | F24: No | G24: 2 | H24: yes | I24: {=_xlfn.IFS(B24<18.5,"Underweight",B24<25,"Normal Weight",B24<30,"Overweight",B24>=30,"Obesity")} -> Obesity | J24: {=_xlfn.IFS(C24<5.7,"Normal",C24<6.5,"Pre-Diabetes",C24>=6.5,"Diabetes")} -> Pre-Diabetes
A25: Id23 | B25: 31.3 | C25: 11.38 | D25: No | E25: No | F25: No | G25: 3 | H25: yes | I25: {=_xlfn.IFS(B25<18.5,"Underweight",B25<25,"Normal Weight",B25<30,"Overweight",B25>=30,"Obesity")} -> Obesity | J25: {=_xlfn.IFS(C25<5.7,"Normal",C25<6.5,"Pre-Diabetes",C25>=6.5,"Diabetes")} -> Diabetes
A26: Id24 | B26: 41.8 | C26: 7.89 | D26: yes | E26: No | F26: No | G26: 2 | H26: yes | I26: {=_xlfn.IFS(B26<18.5,"Underweight",B26<25,"Normal Weight",B26<30,"Overweight",B26>=30,"Obesity")} -> Obesity | J26: {=_xlfn.IFS(C26<5.7,"Normal",C26<6.5,"Pre-Diabetes",C26>=6.5,"Diabetes")} -> Diabetes
A27: Id25 | B27: 35.09 | C27: 4.38 | D27: yes | E27: No | F27: No | G27: 2 | H27: yes | I27: {=_xlfn.IFS(B27<18.5,"Underweight",B27<25,"Normal Weight",B27<30,"Overweight",B27>=30,"Obesity")} -> Obesity | J27: {=_xlfn.IFS(C27<5.7,"Normal",C27<6.5,"Pre-Diabetes",C27>=6.5,"Diabetes")} -> Normal
A28: Id26 | B28: 33.88 | C28: 7.01 | D28: No | E28: No | F28: No | G28: 3 | H28: yes | I28: {=_xlfn.IFS(B28<18.5,"Underweight",B28<25,"Normal Weight",B28<30,"Overweight",B28>=30,"Obesity")} -> Obesity | J28: {=_xlfn.IFS(C28<5.7,"Normal",C28<6.5,"Pre-Diabetes",C28>=6.5,"Diabetes")} -> Diabetes
... A2337: Id2335 | B2337: 17.58 | C2337: 4.51 | D2337: No | E2337: No | F2337: No | G2337: 1 | H2337: No | I2337: {=_xlfn.IFS(B2337<18.5,"Underweight",B2337<25,"Normal Weight",B2337<30,"Overweight",B2337>=30,"Obesity")} -> Underweight | J2337: {=_xlfn.IFS(C2337<5.7,"Normal",C2337<6.5,"Pre-Diabetes",C2337>=6.5,"Diabetes")} -> Normal

Sheet Data Transformation 3
A2: Customer ID | B2: year | C2: month | D2: date | E2: Date of Birth | F2: Age | G2: children | H2: charges | I2: Hospital tier | J2: City tier | K2: State ID
A3: Id2335 | B3: 1992 | C3: Jul | D3: 9 | E3: =_xlfn.CONCAT(D3,"-",C3,"-",B3) -> 9-Jul-1992 | F3: =DATEDIF(E3,"08-6-2023","y") -> 30 | G3: 0 | H3: 563.84 | I3: tier - 2 | J3: tier - 3 | K3: R1013
A4: Id2334 | B4: 1992 | C4: Nov | D4: 30 | E4: =_xlfn.CONCAT(D4,"-",C4,"-",B4) -> 30-Nov-1992 | F4: =DATEDIF(E4,"08-6-2023","y") -> 30 | G4: 0 | H4: 570.62 | I4: tier - 2 | J4: tier - 1 | K4: R1013
A5: Id2333 | B5: 1993 | C5: Jun | D5: 30 | E5: =_xlfn.CONCAT(D5,"-",C5,"-",B5) -> 30-Jun-1993 | F5: =DATEDIF(E5,"08-6-2023","y") -> 29 | G5: 0 | H5: 600 | I5: tier - 2 | J5: tier - 1 | K5: R1013
A6: Id2332 | B6: 1992 | C6: Sep | D6: 13 | E6: =_xlfn.CONCAT(D6,"-",C6,"-",B6) -> 13-Sep-1992 | F6: =DATEDIF(E6,"08-6-2023","y") -> 30 | G6: 0 | H6: 604.54 | I6: tier - 3 | J6: tier - 3 | K6: R1013
A7: Id2331 | B7: 1998 | C7: Jul | D7: 27 | E7: =_xlfn.CONCAT(D7,"-",C7,"-",B7) -> 27-Jul-1998 | F7: =DATEDIF(E7,"08-6-2023","y") -> 24 | G7: 0 | H7: 637.26 | I7: tier - 3 | J7: tier - 3 | K7: R1013 | M7: Merge date, month, year in DOB Column
A8: Id2330 | B8: 2001 | C8: Nov | D8: 20 | E8: =_xlfn.CONCAT(D8,"-",C8,"-",B8) -> 20-Nov-2001 | F8: =DATEDIF(E8,"08-6-2023","y") -> 21 | G8: 0 | H8: 646.14 | I8: tier - 3 | J8: tier - 3 | K8: R1012 | M8: used concat and formatted to short date
A9: Id2329 | B9: 1993 | C9: Jun | D9: 1 | E9: =_xlfn.CONCAT(D9,"-",C9,"-",B9) -> 1-Jun-1993 | F9: =DATEDIF(E9,"08-6-2023","y") -> 30 | G9: 0 | H9: 650 | I9: tier - 3 | J9: tier - 3 | K9: R1013
A10: Id2328 | B10: 1995 | C10: Jul | D10: 4 | E10: =_xlfn.CONCAT(D10,"-",C10,"-",B10) -> 4-Jul-1995 | F10: =DATEDIF(E10,"08-6-2023","y") -> 27 | G10: 0 | H10: 650 | I10: tier - 3 | J10: tier - 3 | K10: R1013 | M10: Calculate Age
A11: Id2327 | B11: 2002 | C11: Nov | D11: 29 | E11: =_xlfn.CONCAT(D11,"-",C11,"-",B11) -> 29-Nov-2002 | F11: =DATEDIF(E11,"08-6-2023","y") -> 20 | G11: 0 | H11: 668 | I11: tier - 3 | J11: tier - 2 | K11: R1012 | M11: used datedif
A12: Id2326 | B12: 1997 | C12: Nov | D12: 9 | E12: =_xlfn.CONCAT(D12,"-",C12,"-",B12) -> 9-Nov-1997 | F12: =DATEDIF(E12,"08-6-2023","y") -> 25 | G12: 0 | H12: 670 | I12: tier - 3 | J12: tier - 3 | K12: R1013
A13: Id2325 | B13: 2001 | C13: Sep | D13: 12 | E13: =_xlfn.CONCAT(D13,"-",C13,"-",B13) -> 12-Sep-2001 | F13: =DATEDIF(E13,"08-6-2023","y") -> 21 | G13: 0 | H13: 687.54 | I13: tier - 3 | J13: tier - 2 | K13: R1013 | M13: Charges column formatted to currency($)
A14: Id2324 | B14: 1999 | C14: Dec | D14: 26 | E14: =_xlfn.CONCAT(D14,"-",C14,"-",B14) -> 26-Dec-1999 | F14: =DATEDIF(E14,"08-6-2023","y") -> 23 | G14: 0 | H14: 700 | I14: tier - 2 | J14: tier - 3 | K14: R1013
A15: Id2323 | B15: 1999 | C15: Dec | D15: 14 | E15: =_xlfn.CONCAT(D15,"-",C15,"-",B15) -> 14-Dec-1999 | F15: =DATEDIF(E15,"08-6-2023","y") -> 23 | G15: 0 | H15: 722.99 | I15: tier - 3 | J15: tier - 1 | K15: R1013 | M15: missing customer ID Values
A16: Id2322 | B16: 2002 | C16: Sep | D16: 19 | E16: =_xlfn.CONCAT(D16,"-",C16,"-",B16) -> 19-Sep-2002 | F16: =DATEDIF(E16,"08-6-2023","y") -> 20 | G16: 0 | H16: 750 | I16: tier - 3 | J16: tier - 1 | K16: R1012 | M16: 6--> removed
A17: Id2321 | B17: 1993 | C17: Aug | D17: 9 | E17: =_xlfn.CONCAT(D17,"-",C17,"-",B17) -> 9-Aug-1993 | F17: =DATEDIF(E17,"08-6-2023","y") -> 29 | G17: 0 | H17: 760 | I17: tier - 3 | J17: tier - 1 | K17: R1013
A18: Id2320 | B18: 1996 | C18: Oct | D18: 22 | E18: =_xlfn.CONCAT(D18,"-",C18,"-",B18) -> 22-Oct-1996 | F18: =DATEDIF(E18,"08-6-2023","y") -> 26 | G18: 0 | H18: 760 | I18: tier - 3 | J18: tier - 3 | K18: R1013
A19: Id2319 | B19: 1993 | C19: Jun | D19: 28 | E19: =_xlfn.CONCAT(D19,"-",C19,"-",B19) -> 28-Jun-1993 | F19: =DATEDIF(E19,"08-6-2023","y") -> 29 | G19: 0 | H19: 770 | I19: tier - 3 | J19: tier - 3 | K19: R1013
A20: Id2318 | B20: 1996 | C20: Sep | D20: 18 | E20: =_xlfn.CONCAT(D20,"-",C20,"-",B20) -> 18-Sep-1996 | F20: =DATEDIF(E20,"08-6-2023","y") -> 26 | G20: 0 | H20: 770.38 | I20: tier - 3 | J20: tier - 2 | K20: R1012
A21: Id2317 | B21: 1995 | C21: Dec | D21: 7 | E21: =_xlfn.CONCAT(D21,"-",C21,"-",B21) -> 7-Dec-1995 | F21: =DATEDIF(E21,"08-6-2023","y") -> 27 | G21: 0 | H21: 773.54 | I21: tier - 3 | J21: tier - 2 | K21: R1013
A22: Id2316 | B22: 2004 | C22: Oct | D22: 7 | E22: =_xlfn.CONCAT(D22,"-",C22,"-",B22) -> 7-Oct-2004 | F22: =DATEDIF(E22,"08-6-2023","y") -> 18 | G22: 0 | H22: 830.52 | I22: tier - 3 | J22: tier - 2 | K22: R1011
A23: Id2315 | B23: 2000 | C23: Nov | D23: 18 | E23: =_xlfn.CONCAT(D23,"-",C23,"-",B23) -> 18-Nov-2000 | F23: =DATEDIF(E23,"08-6-2023","y") -> 22 | G23: 0 | H23: 865.41 | I23: tier - 3 | J23: tier - 1 | K23: R1013
A24: Id2314 | B24: 1993 | C24: Nov | D24: 27 | E24: =_xlfn.CONCAT(D24,"-",C24,"-",B24) -> 27-Nov-1993 | F24: =DATEDIF(E24,"08-6-2023","y") -> 29 | G24: 0 | H24: 896.21 | I24: tier - 3 | J24: tier - 1 | K24: R1013
A25: Id2313 | B25: 1994 | C25: Oct | D25: 30 | E25: =_xlfn.CONCAT(D25,"-",C25,"-",B25) -> 30-Oct-1994 | F25: =DATEDIF(E25,"08-6-2023","y") -> 28 | G25: 0 | H25: 915.07 | I25: tier - 3 | J25: tier - 1 | K25: R1013
A26: Id2312 | B26: 1995 | C26: Oct | D26: 28 | E26: =_xlfn.CONCAT(D26,"-",C26,"-",B26) -> 28-Oct-1995 | F26: =DATEDIF(E26,"08-6-2023","y") -> 27 | G26: 0 | H26: 928.59 | I26: tier - 3 | J26: tier - 1 | K26: R1013
A27: Id2311 | B27: 2001 | C27: Aug | D27: 19 | E27: =_xlfn.CONCAT(D27,"-",C27,"-",B27) -> 19-Aug-2001 | F27: =DATEDIF(E27,"08-6-2023","y") -> 21 | G27: 0 | H27: 964.71 | I27: tier - 3 | J27: tier - 2 | K27: R1013
A28: Id2310 | B28: 1994 | C28: Nov | D28: 22 | E28: =_xlfn.CONCAT(D28,"-",C28,"-",B28) -> 22-Nov-1994 | F28: =DATEDIF(E28,"08-6-2023","y") -> 28 | G28: 0 | H28: 1006.65 | I28: tier - 3 | J28: tier - 2 | K28: R1013
... A2339: Id1 | B2339: 1968 | C2339: Oct | D2339: 12 | E2339: =_xlfn.CONCAT(D2339,"-",C2339,"-",B2339) -> 12-Oct-1968 | F2339: =DATEDIF(E2339,"08-6-2023","y") -> 54 | G2339: 0 | H2339: 63770.43 | I2339: tier - 1 | J2339: tier - 3 | K2339: R1013

Sheet Healthcare 
A1: Customer ID | B1: First Name | C1: BMI | D1: HBA1C | E1: Heart Issues | F1: Any Transplants | G1: Cancer history | H1: NumberOfMajorSurgeries | I1: smoker | J1: Weight Status | K1: Diabetes Status | L1: Date of Birth | M1: charges | N1: Hospital tier | O1: City tier | P1: State ID | Q1: Age
A2: Id1 | B2: =VLOOKUP(A2,'Data Transformation 1.'!A$2:B$2337,2,0) -> Kelly | C2: {=_xlfn.XLOOKUP(A2,'Data transformation 2'!A3:A2337,'Data transformation 2'!B3:J2337)} -> 47.41 | D2: 7.47 | E2: No | F2: No | G2: No | H2: 0 | I2: yes | J2: Obesity | K2: Diabetes | L2: =VLOOKUP(A2,'Data Transformation 3'!A$3:E$2339,5,0) -> 12-Oct-1968 | M2: =VLOOKUP(A2,'Data Transformation 3'!A$3:H$2339,8,0) -> 63770.43 | N2: =VLOOKUP('Healthcare '!A2,'Data Transformation 3'!A$3:I$2339,9,0) -> tier - 1 | O2: =VLOOKUP(A2,'Data Transformation 3'!A$3:J$2339,10,0) -> tier - 3 | P2: =VLOOKUP(A2,'Data Transformation 3'!A$3:K$2339,11,0) -> R1013 | Q2: =VLOOKUP(A2,'Data Transformation 3'!A$3:F$2339,6,0) -> 54
A3: Id2 | B3: =VLOOKUP(A3,'Data Transformation 1.'!A$2:B$2337,2,0) -> Matthew D | C3: {=_xlfn.XLOOKUP(A3,'Data transformation 2'!A4:A2338,'Data transformation 2'!B4:J2338)} -> 30.36 | D3: 5.77 | E3: No | F3: No | G3: No | H3: 0 | I3: yes | J3: Obesity | K3: Pre-Diabetes | L3: =VLOOKUP(A3,'Data Transformation 3'!A$3:E$2339,5,0) -> 8-Jun-1977 | M3: =VLOOKUP(A3,'Data Transformation 3'!A$3:H$2339,8,0) -> 62592.87 | N3: =VLOOKUP('Healthcare '!A3,'Data Transformation 3'!A$3:I$2339,9,0) -> tier - 2 | O3: =VLOOKUP(A3,'Data Transformation 3'!A$3:J$2339,10,0) -> tier - 3 | P3: =VLOOKUP(A3,'Data Transformation 3'!A$3:K$2339,11,0) -> R1013 | Q3: =VLOOKUP(A3,'Data Transformation 3'!A$3:F$2339,6,0) -> 46
A4: Id3 | B4: =VLOOKUP(A4,'Data Transformation 1.'!A$2:B$2337,2,0) -> Phil | C4: {=_xlfn.XLOOKUP(A4,'Data transformation 2'!A5:A2339,'Data transformation 2'!B5:J2339)} -> 34.485 | D4: 11.87 | E4: yes | F4: No | G4: No | H4: 2 | I4: yes | J4: Obesity | K4: Diabetes | L4: =VLOOKUP(A4,'Data Transformation 3'!A$3:E$2339,5,0) -> 11-Sep-1970 | M4: =VLOOKUP(A4,'Data Transformation 3'!A$3:H$2339,8,0) -> 60021.4 | N4: =VLOOKUP('Healthcare '!A4,'Data Transformation 3'!A$3:I$2339,9,0) -> tier - 1 | O4: =VLOOKUP(A4,'Data Transformation 3'!A$3:J$2339,10,0) -> tier - 1 | P4: =VLOOKUP(A4,'Data Transformation 3'!A$3:K$2339,11,0) -> R1012 | Q4: =VLOOKUP(A4,'Data Transformation 3'!A$3:F$2339,6,0) -> 52
A5: Id4 | B5: =VLOOKUP(A5,'Data Transformation 1.'!A$2:B$2337,2,0) -> Kelsey | C5: {=_xlfn.XLOOKUP(A5,'Data transformation 2'!A6:A2340,'Data transformation 2'!B6:J2340)} -> 38.095 | D5: 6.05 | E5: No | F5: No | G5: No | H5: 0 | I5: yes | J5: Obesity | K5: Pre-Diabetes | L5: =VLOOKUP(A5,'Data Transformation 3'!A$3:E$2339,5,0) -> 6-Jun-1991 | M5: =VLOOKUP(A5,'Data Transformation 3'!A$3:H$2339,8,0) -> 58571.07 | N5: =VLOOKUP('Healthcare '!A5,'Data Transformation 3'!A$3:I$2339,9,0) -> tier - 1 | O5: =VLOOKUP(A5,'Data Transformation 3'!A$3:J$2339,10,0) -> tier - 3 | P5: =VLOOKUP(A5,'Data Transformation 3'!A$3:K$2339,11,0) -> R1024 | Q5: =VLOOKUP(A5,'Data Transformation 3'!A$3:F$2339,6,0) -> 32
A6: Id5 | B6: =VLOOKUP(A6,'Data Transformation 1.'!A$2:B$2337,2,0) -> Kristyn | C6: {=_xlfn.XLOOKUP(A6,'Data transformation 2'!A7:A2341,'Data transformation 2'!B7:J2341)} -> 35.53 | D6: 5.45 | E6: No | F6: No | G6: No | H6: 0 | I6: yes | J6: Obesity | K6: Normal | L6: =VLOOKUP(A6,'Data Transformation 3'!A$3:E$2339,5,0) -> 19-Jun-1989 | M6: =VLOOKUP(A6,'Data Transformation 3'!A$3:H$2339,8,0) -> 55135.4 | N6: =VLOOKUP('Healthcare '!A6,'Data Transformation 3'!A$3:I$2339,9,0) -> tier - 1 | O6: =VLOOKUP(A6,'Data Transformation 3'!A$3:J$2339,10,0) -> tier - 2 | P6: =VLOOKUP(A6,'Data Transformation 3'!A$3:K$2339,11,0) -> R1012 | Q6: =VLOOKUP(A6,'Data Transformation 3'!A$3:F$2339,6,0) -> 33
A7: Id6 | B7: =VLOOKUP(A7,'Data Transformation 1.'!A$2:B$2337,2,0) -> Russell B | C7: {=_xlfn.XLOOKUP(A7,'Data transformation 2'!A8:A2342,'Data transformation 2'!B8:J2342)} -> 32.8 | D7: 6.59 | E7: No | F7: No | G7: No | H7: 0 | I7: yes | J7: Obesity | K7: Diabetes | L7: =VLOOKUP(A7,'Data Transformation 3'!A$3:E$2339,5,0) -> 4-Aug-1962 | M7: =VLOOKUP(A7,'Data Transformation 3'!A$3:H$2339,8,0) -> 52590.83 | N7: =VLOOKUP('Healthcare '!A7,'Data Transformation 3'!A$3:I$2339,9,0) -> tier - 1 | O7: =VLOOKUP(A7,'Data Transformation 3'!A$3:J$2339,10,0) -> tier - 3 | P7: =VLOOKUP(A7,'Data Transformation 3'!A$3:K$2339,11,0) -> R1011 | Q7: =VLOOKUP(A7,'Data Transformation 3'!A$3:F$2339,6,0) -> 60
A8: Id7 | B8: =VLOOKUP(A8,'Data Transformation 1.'!A$2:B$2337,2,0) -> Scott | C8: {=_xlfn.XLOOKUP(A8,'Data transformation 2'!A9:A2343,'Data transformation 2'!B9:J2343)} -> 36.4 | D8: 6.07 | E8: No | F8: No | G8: No | H8: 0 | I8: yes | J8: Obesity | K8: Pre-Diabetes | L8: =VLOOKUP(A8,'Data Transformation 3'!A$3:E$2339,5,0) -> 27-Oct-1994 | M8: =VLOOKUP(A8,'Data Transformation 3'!A$3:H$2339,8,0) -> 51194.56 | N8: =VLOOKUP('Healthcare '!A8,'Data Transformation 3'!A$3:I$2339,9,0) -> tier - 1 | O8: =VLOOKUP(A8,'Data Transformation 3'!A$3:J$2339,10,0) -> tier - 3 | P8: =VLOOKUP(A8,'Data Transformation 3'!A$3:K$2339,11,0) -> R1011 | Q8: =VLOOKUP(A8,'Data Transformation 3'!A$3:F$2339,6,0) -> 28
A9: Id8 | B9: =VLOOKUP(A9,'Data Transformation 1.'!A$2:B$2337,2,0) -> Stephen | C9: {=_xlfn.XLOOKUP(A9,'Data transformation 2'!A10:A2344,'Data transformation 2'!B10:J2344)} -> 36.96 | D9: 7.93 | E9: No | F9: No | G9: No | H9: 3 | I9: yes | J9: Obesity | K9: Diabetes | L9: =VLOOKUP(A9,'Data Transformation 3'!A$3:E$2339,5,0) -> 27-Jun-1958 | M9: =VLOOKUP(A9,'Data Transformation 3'!A$3:H$2339,8,0) -> 49577.66 | N9: =VLOOKUP('Healthcare '!A9,'Data Transformation 3'!A$3:I$2339,9,0) -> tier - 2 | O9: =VLOOKUP(A9,'Data Transformation 3'!A$3:J$2339,10,0) -> tier - 2 | P9: =VLOOKUP(A9,'Data Transformation 3'!A$3:K$2339,11,0) -> R1013 | Q9: =VLOOKUP(A9,'Data Transformation 3'!A$3:F$2339,6,0) -> 64
A10: Id9 | B10: =VLOOKUP(A10,'Data Transformation 1.'!A$2:B$2337,2,0) -> Patrick R | C10: {=_xlfn.XLOOKUP(A10,'Data transformation 2'!A11:A2345,'Data transformation 2'!B11:J2345)} -> 41.14 | D10: 9.58 | E10: yes | F10: No | G10: Yes | H10: 1 | I10: yes | J10: Obesity | K10: Diabetes | L10: =VLOOKUP(A10,'Data Transformation 3'!A$3:E$2339,5,0) -> 4-Sep-1963 | M10: =VLOOKUP(A10,'Data Transformation 3'!A$3:H$2339,8,0) -> 48970.25 | N10: =VLOOKUP('Healthcare '!A10,'Data Transformation 3'!A$3:I$2339,9,0) -> tier - 1 | O10: =VLOOKUP(A10,'Data Transformation 3'!A$3:J$2339,10,0) -> tier - 2 | P10: =VLOOKUP(A10,'Data Transformation 3'!A$3:K$2339,11,0) -> R1013 | Q10: =VLOOKUP(A10,'Data Transformation 3'!A$3:F$2339,6,0) -> 59
A11: Id10 | B11: =VLOOKUP(A11,'Data Transformation 1.'!A$2:B$2337,2,0) -> Brooke N | C11: {=_xlfn.XLOOKUP(A11,'Data transformation 2'!A12:A2346,'Data transformation 2'!B12:J2346)} -> 38.06 | D11: 10.79 | E11: No | F11: No | G11: No | H11: 0 | I11: yes | J11: Obesity | K11: Diabetes | L11: =VLOOKUP(A11,'Data Transformation 3'!A$3:E$2339,5,0) -> 29-Dec-1978 | M11: =VLOOKUP(A11,'Data Transformation 3'!A$3:H$2339,8,0) -> 48885.14 | N11: =VLOOKUP('Healthcare '!A11,'Data Transformation 3'!A$3:I$2339,9,0) -> tier - 1 | O11: =VLOOKUP(A11,'Data Transformation 3'!A$3:J$2339,10,0) -> tier - 2 | P11: =VLOOKUP(A11,'Data Transformation 3'!A$3:K$2339,11,0) -> R1013 | Q11: =VLOOKUP(A11,'Data Transformation 3'!A$3:F$2339,6,0) -> 44
A12: Id11 | B12: =VLOOKUP(A12,'Data Transformation 1.'!A$2:B$2337,2,0) -> Paola Andrea | C12: {=_xlfn.XLOOKUP(A12,'Data transformation 2'!A13:A2347,'Data transformation 2'!B13:J2347)} -> 37.7 | D12: 5.96 | E12: yes | F12: No | G12: No | H12: 2 | I12: yes | J12: Obesity | K12: Pre-Diabetes | L12: =VLOOKUP(A12,'Data Transformation 3'!A$3:E$2339,5,0) -> 22-Jul-1959 | M12: =VLOOKUP(A12,'Data Transformation 3'!A$3:H$2339,8,0) -> 48824.45 | N12: =VLOOKUP('Healthcare '!A12,'Data Transformation 3'!A$3:I$2339,9,0) -> tier - 2 | O12: =VLOOKUP(A12,'Data Transformation 3'!A$3:J$2339,10,0) -> tier - 1 | P12: =VLOOKUP(A12,'Data Transformation 3'!A$3:K$2339,11,0) -> R1011 | Q12: =VLOOKUP(A12,'Data Transformation 3'!A$3:F$2339,6,0) -> 63
A13: Id12 | B13: =VLOOKUP(A13,'Data Transformation 1.'!A$2:B$2337,2,0) -> David | C13: {=_xlfn.XLOOKUP(A13,'Data transformation 2'!A14:A2348,'Data transformation 2'!B14:J2348)} -> 42.13 | D13: 11.9 | E13: No | F13: No | G13: No | H13: 0 | I13: yes | J13: Obesity | K13: Diabetes | L13: =VLOOKUP(A13,'Data Transformation 3'!A$3:E$2339,5,0) -> 27-Oct-1965 | M13: =VLOOKUP(A13,'Data Transformation 3'!A$3:H$2339,8,0) -> 48675.52 | N13: =VLOOKUP('Healthcare '!A13,'Data Transformation 3'!A$3:I$2339,9,0) -> tier - 1 | O13: =VLOOKUP(A13,'Data Transformation 3'!A$3:J$2339,10,0) -> tier - 2 | P13: =VLOOKUP(A13,'Data Transformation 3'!A$3:K$2339,11,0) -> R1013 | Q13: =VLOOKUP(A13,'Data Transformation 3'!A$3:F$2339,6,0) -> 57
... A19: Id18 | B19: =VLOOKUP(A19,'Data Transformation 1.'!A$2:B$2337,2,0) -> Christina M | C19: {=_xlfn.XLOOKUP(A19,'Data transformation 2'!A20:A2354,'Data transformation 2'!B20:J2354)} -> 36.765 | D19: 7.29 | E19: yes | F19: No | G19: Yes | H19: 1 | I19: yes | J19: Obesity | K19: Diabetes | L19: =VLOOKUP(A19,'Data Transformation 3'!A$3:E$2339,5,0) -> 5-Aug-1963 | M19: =VLOOKUP(A19,'Data Transformation 3'!A$3:H$2339,8,0) -> 47896.79 | N19: =VLOOKUP('Healthcare '!A19,'Data Transformation 3'!A$3:I$2339,9,0) -> tier - 1 | O19: =VLOOKUP(A19,'Data Transformation 3'!A$3:J$2339,10,0) -> tier - 3 | P19: =VLOOKUP(A19,'Data Transformation 3'!A$3:K$2339,11,0) -> R1024 | Q19: =VLOOKUP(A19,'Data Transformation 3'!A$3:F$2339,6,0) -> 59
A20: Id19 | C20: {=_xlfn.XLOOKUP(A20,'Data transformation 2'!A21:A2355,'Data transformation 2'!B21:J2355)} -> 36.955 | D20: 4.72 | E20: yes | F20: No | G20: No | H20: 1 | I20: yes | J20: Obesity | K20: Normal | L20: =VLOOKUP(A20,'Data Transformation 3'!A$3:E$2339,5,0) -> 7-Nov-1964 | M20: =VLOOKUP(A20,'Data Transformation 3'!A$3:H$2339,8,0) -> 47496.49 | N20: =VLOOKUP('Healthcare '!A20,'Data Transformation 3'!A$3:I$2339,9,0) -> tier - 1 | O20: =VLOOKUP(A20,'Data Transformation 3'!A$3:J$2339,10,0) -> tier - 3 | P20: =VLOOKUP(A20,'Data Transformation 3'!A$3:K$2339,11,0) -> R1012 | Q20: =VLOOKUP(A20,'Data Transformation 3'!A$3:F$2339,6,0) -> 58
A21: Id20 | C21: {=_xlfn.XLOOKUP(A21,'Data transformation 2'!A22:A2356,'Data transformation 2'!B22:J2356)} -> 42.9 | D21: 11.41 | E21: No | F21: No | G21: No | H21: 0 | I21: yes | J21: Obesity | K21: Diabetes | L21: =VLOOKUP(A21,'Data Transformation 3'!A$3:E$2339,5,0) -> 27-Sep-1971 | M21: =VLOOKUP(A21,'Data Transformation 3'!A$3:H$2339,8,0) -> 47462.89 | N21: =VLOOKUP('Healthcare '!A21,'Data Transformation 3'!A$3:I$2339,9,0) -> tier - 1 | O21: =VLOOKUP(A21,'Data Transformation 3'!A$3:J$2339,10,0) -> tier - 2 | P21: =VLOOKUP(A21,'Data Transformation 3'!A$3:K$2339,11,0) -> R1013 | Q21: =VLOOKUP(A21,'Data Transformation 3'!A$3:F$2339,6,0) -> 51
A22: Id21 | C22: {=_xlfn.XLOOKUP(A22,'Data transformation 2'!A23:A2357,'Data transformation 2'!B23:J2357)} -> 36.3 | D22: 11.5 | E22: yes | F22: No | G22: No | H22: 2 | I22: yes | J22: Obesity | K22: Diabetes | L22: =VLOOKUP(A22,'Data Transformation 3'!A$3:E$2339,5,0) -> 13-Jun-1961 | M22: =VLOOKUP(A22,'Data Transformation 3'!A$3:H$2339,8,0) -> 47403.88 | N22: =VLOOKUP('Healthcare '!A22,'Data Transformation 3'!A$3:I$2339,9,0) -> tier - 1 | O22: =VLOOKUP(A22,'Data Transformation 3'!A$3:J$2339,10,0) -> tier - 3 | P22: =VLOOKUP(A22,'Data Transformation 3'!A$3:K$2339,11,0) -> R1011 | Q22: =VLOOKUP(A22,'Data Transformation 3'!A$3:F$2339,6,0) -> 61
A23: Id22 | C23: {=_xlfn.XLOOKUP(A23,'Data transformation 2'!A24:A2358,'Data transformation 2'!B24:J2358)} -> 32.2 | D23: 6.22 | E23: yes | F23: No | G23: No | H23: 2 | I23: yes | J23: Obesity | K23: Pre-Diabetes | L23: =VLOOKUP(A23,'Data Transformation 3'!A$3:E$2339,5,0) -> 4-Oct-1959 | M23: =VLOOKUP(A23,'Data Transformation 3'!A$3:H$2339,8,0) -> 47305.31 | N23: =VLOOKUP('Healthcare '!A23,'Data Transformation 3'!A$3:I$2339,9,0) -> tier - 2 | O23: =VLOOKUP(A23,'Data Transformation 3'!A$3:J$2339,10,0) -> tier - 1 | P23: =VLOOKUP(A23,'Data Transformation 3'!A$3:K$2339,11,0) -> R1011 | Q23: =VLOOKUP(A23,'Data Transformation 3'!A$3:F$2339,6,0) -> 63
A24: Id23 | C24: {=_xlfn.XLOOKUP(A24,'Data transformation 2'!A25:A2359,'Data transformation 2'!B25:J2359)} -> 31.3 | D24: 11.38 | E24: No | F24: No | G24: No | H24: 3 | I24: yes | J24: Obesity | K24: Diabetes | L24: =VLOOKUP(A24,'Data Transformation 3'!A$3:E$2339,5,0) -> 3-Sep-1958 | M24: =VLOOKUP(A24,'Data Transformation 3'!A$3:H$2339,8,0) -> 47291.06 | N24: =VLOOKUP('Healthcare '!A24,'Data Transformation 3'!A$3:I$2339,9,0) -> tier - 2 | O24: =VLOOKUP(A24,'Data Transformation 3'!A$3:J$2339,10,0) -> tier - 1 | P24: =VLOOKUP(A24,'Data Transformation 3'!A$3:K$2339,11,0) -> R1011 | Q24: =VLOOKUP(A24,'Data Transformation 3'!A$3:F$2339,6,0) -> 64
A25: Id24 | C25: {=_xlfn.XLOOKUP(A25,'Data transformation 2'!A26:A2360,'Data transformation 2'!B26:J2360)} -> 41.8 | D25: 7.89 | E25: yes | F25: No | G25: No | H25: 2 | I25: yes | J25: Obesity | K25: Diabetes | L25: =VLOOKUP(A25,'Data Transformation 3'!A$3:E$2339,5,0) -> 28-Dec-1970 | M25: =VLOOKUP(A25,'Data Transformation 3'!A$3:H$2339,8,0) -> 47269.85 | N25: =VLOOKUP('Healthcare '!A25,'Data Transformation 3'!A$3:I$2339,9,0) -> tier - 1 | O25: =VLOOKUP(A25,'Data Transformation 3'!A$3:J$2339,10,0) -> tier - 2 | P25: =VLOOKUP(A25,'Data Transformation 3'!A$3:K$2339,11,0) -> R1013 | Q25: =VLOOKUP(A25,'Data Transformation 3'!A$3:F$2339,6,0) -> 52
A26: Id25 | C26: {=_xlfn.XLOOKUP(A26,'Data transformation 2'!A27:A2361,'Data transformation 2'!B27:J2361)} -> 35.09 | D26: 4.38 | E26: yes | F26: No | G26: No | H26: 2 | I26: yes | J26: Obesity | K26: Normal | L26: =VLOOKUP(A26,'Data Transformation 3'!A$3:E$2339,5,0) -> 14-Jul-1959 | M26: =VLOOKUP(A26,'Data Transformation 3'!A$3:H$2339,8,0) -> 47055.53 | N26: =VLOOKUP('Healthcare '!A26,'Data Transformation 3'!A$3:I$2339,9,0) -> tier - 2 | O26: =VLOOKUP(A26,'Data Transformation 3'!A$3:J$2339,10,0) -> tier - 1 | P26: =VLOOKUP(A26,'Data Transformation 3'!A$3:K$2339,11,0) -> R1013 | Q26: =VLOOKUP(A26,'Data Transformation 3'!A$3:F$2339,6,0) -> 63
A27: Id26 | C27: {=_xlfn.XLOOKUP(A27,'Data transformation 2'!A28:A2362,'Data transformation 2'!B28:J2362)} -> 33.88 | D27: 7.01 | E27: No | F27: No | G27: No | H27: 3 | I27: yes | J27: Obesity | K27: Diabetes | L27: =VLOOKUP(A27,'Data Transformation 3'!A$3:E$2339,5,0) -> 15-Sep-1958 | M27: =VLOOKUP(A27,'Data Transformation 3'!A$3:H$2339,8,0) -> 46889.26 | N27: =VLOOKUP('Healthcare '!A27,'Data Transformation 3'!A$3:I$2339,9,0) -> tier - 2 | O27: =VLOOKUP(A27,'Data Transformation 3'!A$3:J$2339,10,0) -> tier - 3 | P27: =VLOOKUP(A27,'Data Transformation 3'!A$3:K$2339,11,0) -> R1013 | Q27: =VLOOKUP(A27,'Data Transformation 3'!A$3:F$2339,6,0) -> 64
A28: Id27 | C28: {=_xlfn.XLOOKUP(A28,'Data transformation 2'!A29:A2363,'Data transformation 2'!B29:J2363)} -> 30.875 | D28: 11.88 | E28: No | F28: No | G28: No | H28: 0 | I28: yes | J28: Obesity | K28: Diabetes | L28: =VLOOKUP(A28,'Data Transformation 3'!A$3:E$2339,5,0) -> 17-Nov-1960 | M28: =VLOOKUP(A28,'Data Transformation 3'!A$3:H$2339,8,0) -> 46718.16 | N28: =VLOOKUP('Healthcare '!A28,'Data Transformation 3'!A$3:I$2339,9,0) -> tier - 1 | O28: =VLOOKUP(A28,'Data Transformation 3'!A$3:J$2339,10,0) -> tier - 1 | P28: =VLOOKUP(A28,'Data Transformation 3'!A$3:K$2339,11,0) -> R1012 | Q28: =VLOOKUP(A28,'Data Transformation 3'!A$3:F$2339,6,0) -> 62
A29: Id28 | C29: {=_xlfn.XLOOKUP(A29,'Data transformation 2'!A30:A2364,'Data transformation 2'!B30:J2364)} -> 36.86 | D29: 5.19 | E29: yes | F29: No | G29: Yes | H29: 1 | I29: yes | J29: Obesity | K29: Normal | L29: =VLOOKUP(A29,'Data Transformation 3'!A$3:E$2339,5,0) -> 23-Jun-1969 | M29: =VLOOKUP(A29,'Data Transformation 3'!A$3:H$2339,8,0) -> 46661.44 | N29: =VLOOKUP('Healthcare '!A29,'Data Transformation 3'!A$3:I$2339,9,0) -> tier - 1 | O29: =VLOOKUP(A29,'Data Transformation 3'!A$3:J$2339,10,0) -> tier - 3 | P29: =VLOOKUP(A29,'Data Transformation 3'!A$3:K$2339,11,0) -> R1012 | Q29: =VLOOKUP(A29,'Data Transformation 3'!A$3:F$2339,6,0) -> 53
A30: Id29 | C30: {=_xlfn.XLOOKUP(A30,'Data transformation 2'!A31:A2365,'Data transformation 2'!B31:J2365)} -> 35.86 | D30: 6.74 | E30: yes | F30: No | G30: No | H30: 2 | I30: yes | J30: Obesity | K30: Diabetes | L30: =VLOOKUP(A30,'Data Transformation 3'!A$3:E$2339,5,0) -> 8-Aug-1961 | M30: =VLOOKUP(A30,'Data Transformation 3'!A$3:H$2339,8,0) -> 46599.11 | N30: =VLOOKUP('Healthcare '!A30,'Data Transformation 3'!A$3:I$2339,9,0) -> tier - 1 | O30: =VLOOKUP(A30,'Data Transformation 3'!A$3:J$2339,10,0) -> tier - 1 | P30: =VLOOKUP(A30,'Data Transformation 3'!A$3:K$2339,11,0) -> R1013 | Q30: =VLOOKUP(A30,'Data Transformation 3'!A$3:F$2339,6,0) -> 61
A31: Id30 | C31: {=_xlfn.XLOOKUP(A31,'Data transformation 2'!A32:A2366,'Data transformation 2'!B32:J2366)} -> 37.05 | D31: 8.44 | E31: No | F31: No | G31: No | H31: 0 | I31: yes | J31: Obesity | K31: Diabetes | L31: =VLOOKUP(A31,'Data Transformation 3'!A$3:E$2339,5,0) -> 6-Dec-1971 | M31: =VLOOKUP(A31,'Data Transformation 3'!A$3:H$2339,8,0) -> 46255.11 | N31: =VLOOKUP('Healthcare '!A31,'Data Transformation 3'!A$3:I$2339,9,0) -> tier - 1 | O31: =VLOOKUP(A31,'Data Transformation 3'!A$3:J$2339,10,0) -> tier - 3 | P31: =VLOOKUP(A31,'Data Transformation 3'!A$3:K$2339,11,0) -> R1024 | Q31: =VLOOKUP(A31,'Data Transformation 3'!A$3:F$2339,6,0) -> 51
... A2336: Id2335 | C2336: {=_xlfn.XLOOKUP(A2336,'Data transformation 2'!A2337:A4671,'Data transformation 2'!B2337:J4671)} -> 17.58 | D2336: 4.51 | E2336: No | F2336: No | G2336: No | H2336: 1 | I2336: No | J2336: Underweight | K2336: Normal | L2336: =VLOOKUP(A2336,'Data Transformation 3'!A$3:E$2339,5,0) -> 9-Jul-1992 | M2336: =VLOOKUP(A2336,'Data Transformation 3'!A$3:H$2339,8,0) -> 563.84 | N2336: =VLOOKUP('Healthcare '!A2336,'Data Transformation 3'!A$3:I$2339,9,0) -> tier - 2 | O2336: =VLOOKUP(A2336,'Data Transformation 3'!A$3:J$2339,10,0) -> tier - 3 | P2336: =VLOOKUP(A2336,'Data Transformation 3'!A$3:K$2339,11,0) -> R1013 | Q2336: =VLOOKUP(A2336,'Data Transformation 3'!A$3:F$2339,6,0) -> 30

Sheet Analysis-Pie
B3: 1 | C3: What is the distribution of cancer history among smokers and non-smokers?
C5: Count of Customer ID | D5: Smoker
C6: Cancer History | D6: No | E6: yes | F6: Grand Total
C7: No | D7: 1540 | E7: 404 | F7: 1944
C8: Yes | D8: 307 | E8: 84 | F8: 391
C9: Grand Total | D9: 1847 | E9: 488 | F9: 2335
B19: 2 | C19: How does the total number of major surgeries and average HbA1C differ between patients with and without a history of transplants?
C22: Average of HBA1C | D22: Any Transplants?
C23: Total Major Surgeries | D23: No | E23: yes | F23: Grand Total
C24: 0 | D24: 7.1031378 | F24: 7.1031378
C25: 1 | D25: 5.9088319 | E25: 5.1646032 | F25: 5.811658
C26: 2 | D26: 7.1386719 | E26: 5.3488889 | F26: 7.0210949
C27: 3 | D27: 9.1436364 | F27: 9.1436364
C28: Grand Total | D28: 6.6704427 | E28: 5.1876389 | F28: 6.5789979

Sheet Analysis-column
B3: 1 | C3: How do healthcare charges vary based on different weight statuses and diabetes statuses?
C5: Average of charges | D5: Diabetes status
C6: Weight status | D6: Diabetes | E6: Normal | F6: Pre-Diabetes | G6: Grand Total
C7: Normal Weight | D7: 12447.613 | E7: 7938.5057 | F7: 10492.131 | G7: 9851.9225
C8: Obesity | D8: 19347.657 | E8: 15188.437 | F8: 15353.902 | G8: 16661.463
C9: Overweight | D9: 14269.014 | E9: 10327.157 | F9: 9737.9402 | G9: 11435.413
C10: Underweight | D10: 7442.9649 | E10: 6911.0056 | F10: 5647.7483 | G10: 6899.3175
C11: Grand Total | D11: 16120.287 | E11: 12090.723 | F11: 12532.263 | G11: 13529.918
B19: 2 | C19: Can you compare the average charges for each hospital tier within different states?
C22: Average of charges | D22: Hospital Tier
C23: State IDs | D23: tier - 1 | E23: tier - 2 | F23: tier - 3 | G23: Grand Total
C24: R1011 | D24: 33081.374 | E24: 18997.281 | F24: 9250.3618 | G24: 19466.246
C25: R1017 | D25: 34070.596 | E25: 11365.622 | F25: 8667.3662 | G25: 14806.108
C26: R1015 | D26: 21523.52 | E26: 15675.543 | F26: 7570.755 | G26: 13948.61
C27: R1023 | D27: 18261.757 | E27: 13457.095 | F27: 12785.637 | G27: 13786.149
C28: R1019 | D28: 27621.61 | E28: 8116.72 | F28: 12706.976 | G28: 13633.143
C29: R1016 | D29: 39868.616 | E29: 16075.963 | F29: 8133.0084 | G29: 13589.263
C30: R1014 | D30: 13891.86 | E30: 2395.17 | F30: 16950.485 | G30: 13478.057
C31: R1018 | D31: 33475.82 | E31: 10139.553 | F31: 12570.97 | G31: 13272.787
C32: R1024 | D32: 32732.187 | E32: 10174.346 | F32: 13360.979 | G32: 12865.149
C33: R1026 | D33: 18709.798 | E33: 11919.608 | F33: 12296.78 | G33: 12489.921
C34: R1012 | D34: 26111.458 | E34: 10334.279 | F34: 10179.942 | G34: 12016.474
C35: R1022 | E35: 10102.027 | F35: 11637.812 | G35: 10650.521
C36: R1013 | D36: 31328.102 | E36: 8439.2844 | F36: 6890.7568 | G36: 10514.94
C37: R1020 | E37: 6760.5433 | F37: 11716.453 | G37: 9238.4983
C38: R1021 | E38: 7668.1787 | F38: 11518.786 | G38: 8933.3781
C39: R1025 | E39: 6886.0368 | F39: 10510.314 | G39: 8788.7823
C40: Grand Total | D40: 30189.68 | E40: 11865.269 | F40: 9462.2693 | G40: 13523.517
C43: Average of charges | D43: Hospital Tier
C44: State IDs | D44: tier - 1 | E44: tier - 2 | F44: tier - 3 | G44: Sum
C45: R1016 | D45: 39868.616 | E45: 16075.963 | F45: 8133.0084 | G45: =SUM(D45:F45) -> 64077.588
C46: R1011 | D46: 33081.374 | E46: 18997.281 | F46: 9250.3618 | G46: =SUM(D46:F46) -> 61329.016
C47: R1024 | D47: 32732.187 | E47: 10174.346 | F47: 13360.979 | G47: =SUM(D47:F47) -> 56267.512
C48: R1018 | D48: 33475.82 | E48: 10139.553 | F48: 12570.97 | G48: =SUM(D48:F48) -> 56186.343
C49: R1017 | D49: 34070.596 | E49: 11365.622 | F49: 8667.3662 | G49: =SUM(D49:F49) -> 54103.584
C50: R1019 | D50: 27621.61 | E50: 8116.72 | F50: 12706.976 | G50: =SUM(D50:F50) -> 48445.306
C51: R1013 | D51: 31328.102 | E51: 8439.2844 | F51: 6890.7568 | G51: =SUM(D51:F51) -> 46658.143
C52: R1012 | D52: 26111.458 | E52: 10334.279 | F52: 10179.942 | G52: =SUM(D52:F52) -> 46625.679
C53: R1015 | D53: 21523.52 | E53: 15675.543 | F53: 7570.755 | G53: =SUM(D53:F53) -> 44769.818
C54: R1023 | D54: 18261.757 | E54: 13457.095 | F54: 12785.637 | G54: =SUM(D54:F54) -> 44504.489
...

Sheet Analysis-line
B3: 1 | C3: Is there any correlation between age and both BMI and HbA1C in the dataset?
C5: Age | D5: Average of BMI | E5: Average of HBA1C
C6: 18 | D6: 31.260372 | E6: 5.1409574
C7: 19 | D7: 29.654186 | E7: 5.1781395
C8: 20 | D8: 28.018276 | E8: 9.3244828
C9: 21 | D9: 29.273721 | E9: 5.1174419
C10: 22 | D10: 32.581827 | E10: 5.2767308
C11: 23 | D11: 30.8293 | E11: 5.1892
C12: 24 | D12: 29.0175 | E12: 5.1626087
C13: 25 | D13: 30.344211 | E13: 5.2589474
C14: 26 | D14: 30.441364 | E14: 5.1029545
C15: 27 | D15: 30.316275 | E15: 4.9407843
C16: 28 | D16: 31.029286 | E16: 5.2207143
C17: 29 | D17: 30.763302 | E17: 5.2043396
... C53: 65 | D53: 26.885 | E53: 9.86
C54: Grand Total | D54: 30.972649 | E54: 6.5789979
B57: 2 | C57: Explore the relationship between age and healthcare charges.
C59: Age | D59: Average of charges
C60: 18 | D60: 6611.3116
C61: 19 | D61: 9677.1869
C62: 20 | D62: 7411.4483
C63: 21 | D63: 5214.5293
C64: 22 | D64: 9806.2325
C65: 23 | D65: 11092.934
C66: 24 | D66: 9765.5713
C67: 25 | D67: 9184.887
C68: 26 | D68: 5920.5868
C69: 27 | D69: 11846.242
C70: 28 | D70: 9219.8155
C71: 29 | D71: 9914.8
... C107: 65 | D107: 29330.98
C108: Grand Total | D108: 13529.918

Sheet Interactive Dashboard
